Workbook

Sheet QC_CHECK
A1: QC_CHECK — Multi-validation & Gate (v3)
A3: Check | B3: Formula / Logic | C3: Result | D3: Status
A4: Symbol present | B4: CONTROL!B3<>"" | C4: =IF(CONTROL!B3<>"","OK","MISSING") | D4: =IF(C4="OK","PASS","FAIL")
A5: Spot present | B5: CONTROL!B4<>"" | C5: =IF(CONTROL!B4<>"","OK","MISSING") | D5: =IF(C5="OK","PASS","FAIL")
A6: Lot size present | B6: CONTROL!B5<>"" | C6: =IF(CONTROL!B5<>"","OK","MISSING") | D6: =IF(C6="OK","PASS","FAIL")
A7: Expiry present | B7: CONTROL!B7<>"" | C7: =IF(CONTROL!B7<>"","OK","MISSING") | D7: =IF(C7="OK","PASS","FAIL")
A8: Capital present | B8: CONTROL!B11<>"" | C8: =IF(CONTROL!B11<>"","OK","MISSING") | D8: =IF(C8="OK","PASS","FAIL")
A9: Chain rows present | B9: COUNTA(tblChainRaw[Identifier])>0 | C9: =IF(COUNTA(tblChainRaw[Identifier])>0,"OK","NO DATA") | D9: =IF(C9="OK","PASS","FAIL")
A10: Ask >= Bid where present | B10: SUMPRODUCT(--(tblChainRaw[Ask Price]<>""),--(tblChainRaw[Bid Price]<>""),--(tblChainRaw[Ask Price]<tblChainRaw[Bid Price]))=0 | C10: =LET(v,SUMPRODUCT(--(tblChainRaw[Ask Price]<>""),--(tblChainRaw[Bid Price]<>""),--(tblChainRaw[Ask Price]<tblChainRaw[Bid Price])),IF(v=0,"OK",v&" violations")) | D10: =IF(LEFT(C10,2)="OK","PASS","FAIL")
A11: IV decimal in [0,3] | B11: MAX(tblChainRaw[IV (decimal)])<=3 | C11: =IF(MAX(tblChainRaw[IV (decimal)])<=3,"OK","IV TOO HIGH") | D11: =IF(C11="OK","PASS","FAIL")
A12: IV non-negative | B12: MIN(tblChainRaw[IV (decimal)])>=0 | C12: =IF(MIN(tblChainRaw[IV (decimal)])>=0,"OK","NEGATIVE IV") | D12: =IF(C12="OK","PASS","FAIL")
A13: Greeks T positive (row4) | B13: GREEKS!G4>0 | C13: =IF(GREEKS!G4>0,"OK","BAD T") | D13: =IF(C13="OK","PASS","FAIL")
A14: Expected Move computed | B14: CHAIN_CALC!B22>0 | C14: =IF(CHAIN_CALC!B22>0,"OK","BAD") | D14: =IF(C14="OK","PASS","FAIL")
A15: Delta PCR computed | B15: DELTA_PCR!B10<>"" | C15: =IF(DELTA_PCR!B10<>"","OK","MISSING") | D15: =IF(C15="OK","PASS","FAIL")
A16: Strategy chosen | B16: STRATEGY_ENGINE!B10<>"" | C16: =IF(STRATEGY_ENGINE!B10<>"","OK","MISSING") | D16: =IF(C16="OK","PASS","FAIL")
A17: Not NO TRADE | B17: STRATEGY_ENGINE!B10<>"NO TRADE" | C17: =IF(STRATEGY_ENGINE!B10<>"NO TRADE","OK","NO TRADE") | D17: =IF(C17="OK","PASS","FAIL")
A18: POP gate pass | B18: PROBABILITY_ENGINE!B12="PASS" | C18: =IF(PROBABILITY_ENGINE!B12="PASS","OK","FAIL") | D18: =IF(C18="OK","PASS","FAIL")
A21: OVERALL GATE | B21: All checks must PASS | C21: =IF(COUNTIF(D4:D19,"FAIL")=0,"ALL PASS","FAILURES") | D21: =IF(C21="ALL PASS","PASS","FAIL")

Sheet HELP
A1: How to use this workbook
A3: Section | B3: Instruction
A4: 1) Set CONTROL inputs | B4: Fill blue cells in CONTROL (Instrument, Expiry, Spot, Strike Step, etc.).
A5: 2) Load live option chain | B5: Fill CHAIN_RAW rows (starting row 3) with one row per strike containing CE & PE fields.
A6: 3) QC gate | B6: Go to QC_CHECK. QC_STATUS must be PASS. If FAIL, fix CHAIN_RAW.
A7: 4) View signals | B7: Open SUMMARY. If QC passes, the Bias/Confidence and trade idea updates automatically.
A8: 5) Log outcomes | B8: After trade, append one row in SIGNALS_LOG to track accuracy and refine rules.
A9: Data format notes | B9: Timestamp must be Excel datetime. IV must be decimal (e.g., 0.15 = 15%). OI/Volume numeric.
A10: No dynamic arrays | B10: Workbook avoids FILTER/XLOOKUP to stay compatible.

Sheet CONTROL
A1: OPTION CHAIN MASTER (REBUILT) — CONTROL PANEL
A3: Inputs (blue)
A4: Market | B4: INDIA | D4: Derived (black/green)
A5: Instrument | B5: NIFTY | D5: ATM Strike | E5: =IFERROR(ROUND($B$7/$B$8,0)*$B$8,"")
A6: Expiry (YYYY-MM-DD) | D6: Spot (fallback from CHAIN_RAW if blank) | E6: =IF($B$7<>"",$B$7,IFERROR(AVERAGE(CHAIN_RAW!$D$2:$D$2001),""))
A7: Spot / Underlying Price | D7: Expiry (fallback from CHAIN_RAW if blank) | E7: =IF($B$6<>"",$B$6,IFERROR(INDEX(CHAIN_RAW!$C$2:$C$2001,1),""))
A8: Strike Step | B8: 50
A9: Timezone | B9: Asia/Kolkata
A10: Data Timestamp (from CHAIN_RAW) | B10: =IFERROR(MAX(CHAIN_RAW!$A$2:$A$2001),"")
A11: Min rows required | B11: 200
A12: Max allowed staleness (seconds) | B12: 30
A13: Risk per trade (%) | B13: 1.0
A14: Max loss per day (%) | B14: 2.0
A15: Mode | B15: INTRADAY
A16: Signal engine | B16: V3_RULES

Sheet CHAIN_RAW
A1: LIVE OPTION CHAIN (RAW) — Paste/Import rows here (no formulas)
A2: Timestamp (Excel datetime) | B2: Symbol | C2: Expiry | D2: Spot | E2: Strike | F2: CE_LTP | G2: CE_IV | H2: CE_OI | I2: CE_ChgOI | J2: CE_Vol | K2: CE_Bid | L2: CE_Ask | M2: PE_LTP | N2: PE_IV | O2: PE_OI | P2: PE_ChgOI | Q2: PE_Vol | R2: PE_Bid | S2: PE_Ask | T2: Source

Sheet CHAIN_CALC
A1: DERIVED OPTION CHAIN METRICS (CALC) — auto from CHAIN_RAW
A2: Timestamp | B2: Symbol | C2: Expiry | D2: Spot | E2: Strike | F2: Moneyness | G2: CE_Mid | H2: PE_Mid | I2: CE_Spread% | J2: PE_Spread% | K2: CE_IV | L2: PE_IV | M2: IV_Skew (PE-CE) | N2: CE_OI | O2: PE_OI | P2: PCR_OI (PE/CE) | Q2: CE_ChgOI | R2: PE_ChgOI | S2: PCR_ChgOI | T2: OI_Wall_Score | U2: Support/Resistance | V2: Build_Type | W2: Signal_Contribution | X2: Notes
A3: =CHAIN_RAW!A3 | B3: =CHAIN_RAW!B3 | C3: =CHAIN_RAW!C3 | D3: =CHAIN_RAW!D3 | E3: =CHAIN_RAW!E3 | F3: =IFERROR((E3-D3)/D3,"") | G3: =IFERROR((CHAIN_RAW!K3+CHAIN_RAW!L3)/2,"") | H3: =IFERROR((CHAIN_RAW!R3+CHAIN_RAW!S3)/2,"") | I3: =IFERROR((CHAIN_RAW!L3-CHAIN_RAW!K3)/MAX(1E-9, G3),"") | J3: =IFERROR((CHAIN_RAW!S3-CHAIN_RAW!R3)/MAX(1E-9, H3),"") | K3: =CHAIN_RAW!G3 | L3: =CHAIN_RAW!N3 | M3: =IFERROR(L3-K3,"") | N3: =CHAIN_RAW!H3 | O3: =CHAIN_RAW!O3 | P3: =IFERROR(O3/N3,"") | Q3: =CHAIN_RAW!I3 | R3: =CHAIN_RAW!P3 | S3: =IFERROR(R3/Q3,"") | T3: =IFERROR((ABS(N3-O3)/MAX(1,(N3+O3)))*EXP(-ABS(E3-CONTROL!E5)/MAX(1,CONTROL!B8)),"") | U3: =IFERROR(IF(O3>N3,"SUPPORT (PE OI)","RESIST (CE OI)"),"") | V3: =IFERROR(IF(Q3>0,IF(R3>0,"BOTH_ADD","CE_ADD_PE_REDUCE"),IF(R3>0,"CE_REDUCE_PE_ADD","BOTH_REDUCE")),"") | W3: =IFERROR( (P3-1)*0.5 + (M3)*0.1 - (I3+J3)*0.05 + T3*0.4 ,"") | X3: =IFERROR(IF(ABS(F3)<0.01,"ATM/NEAR",""),"")
A4: =CHAIN_RAW!A4 | B4: =CHAIN_RAW!B4 | C4: =CHAIN_RAW!C4 | D4: =CHAIN_RAW!D4 | E4: =CHAIN_RAW!E4 | F4: =IFERROR((E4-D4)/D4,"") | G4: =IFERROR((CHAIN_RAW!K4+CHAIN_RAW!L4)/2,"") | H4: =IFERROR((CHAIN_RAW!R4+CHAIN_RAW!S4)/2,"") | I4: =IFERROR((CHAIN_RAW!L4-CHAIN_RAW!K4)/MAX(1E-9, G4),"") | J4: =IFERROR((CHAIN_RAW!S4-CHAIN_RAW!R4)/MAX(1E-9, H4),"") | K4: =CHAIN_RAW!G4 | L4: =CHAIN_RAW!N4 | M4: =IFERROR(L4-K4,"") | N4: =CHAIN_RAW!H4 | O4: =CHAIN_RAW!O4 | P4: =IFERROR(O4/N4,"") | Q4: =CHAIN_RAW!I4 | R4: =CHAIN_RAW!P4 | S4: =IFERROR(R4/Q4,"") | T4: =IFERROR((ABS(N4-O4)/MAX(1,(N4+O4)))*EXP(-ABS(E4-CONTROL!E5)/MAX(1,CONTROL!B8)),"") | U4: =IFERROR(IF(O4>N4,"SUPPORT (PE OI)","RESIST (CE OI)"),"") | V4: =IFERROR(IF(Q4>0,IF(R4>0,"BOTH_ADD","CE_ADD_PE_REDUCE"),IF(R4>0,"CE_REDUCE_PE_ADD","BOTH_REDUCE")),"") | W4: =IFERROR( (P4-1)*0.5 + (M4)*0.1 - (I4+J4)*0.05 + T4*0.4 ,"") | X4: =IFERROR(IF(ABS(F4)<0.01,"ATM/NEAR",""),"")
A5: =CHAIN_RAW!A5 | B5: =CHAIN_RAW!B5 | C5: =CHAIN_RAW!C5 | D5: =CHAIN_RAW!D5 | E5: =CHAIN_RAW!E5 | F5: =IFERROR((E5-D5)/D5,"") | G5: =IFERROR((CHAIN_RAW!K5+CHAIN_RAW!L5)/2,"") | H5: =IFERROR((CHAIN_RAW!R5+CHAIN_RAW!S5)/2,"") | I5: =IFERROR((CHAIN_RAW!L5-CHAIN_RAW!K5)/MAX(1E-9, G5),"") | J5: =IFERROR((CHAIN_RAW!S5-CHAIN_RAW!R5)/MAX(1E-9, H5),"") | K5: =CHAIN_RAW!G5 | L5: =CHAIN_RAW!N5 | M5: =IFERROR(L5-K5,"") | N5: =CHAIN_RAW!H5 | O5: =CHAIN_RAW!O5 | P5: =IFERROR(O5/N5,"") | Q5: =CHAIN_RAW!I5 | R5: =CHAIN_RAW!P5 | S5: =IFERROR(R5/Q5,"") | T5: =IFERROR((ABS(N5-O5)/MAX(1,(N5+O5)))*EXP(-ABS(E5-CONTROL!E5)/MAX(1,CONTROL!B8)),"") | U5: =IFERROR(IF(O5>N5,"SUPPORT (PE OI)","RESIST (CE OI)"),"") | V5: =IFERROR(IF(Q5>0,IF(R5>0,"BOTH_ADD","CE_ADD_PE_REDUCE"),IF(R5>0,"CE_REDUCE_PE_ADD","BOTH_REDUCE")),"") | W5: =IFERROR( (P5-1)*0.5 + (M5)*0.1 - (I5+J5)*0.05 + T5*0.4 ,"") | X5: =IFERROR(IF(ABS(F5)<0.01,"ATM/NEAR",""),"")
A6: =CHAIN_RAW!A6 | B6: =CHAIN_RAW!B6 | C6: =CHAIN_RAW!C6 | D6: =CHAIN_RAW!D6 | E6: =CHAIN_RAW!E6 | F6: =IFERROR((E6-D6)/D6,"") | G6: =IFERROR((CHAIN_RAW!K6+CHAIN_RAW!L6)/2,"") | H6: =IFERROR((CHAIN_RAW!R6+CHAIN_RAW!S6)/2,"") | I6: =IFERROR((CHAIN_RAW!L6-CHAIN_RAW!K6)/MAX(1E-9, G6),"") | J6: =IFERROR((CHAIN_RAW!S6-CHAIN_RAW!R6)/MAX(1E-9, H6),"") | K6: =CHAIN_RAW!G6 | L6: =CHAIN_RAW!N6 | M6: =IFERROR(L6-K6,"") | N6: =CHAIN_RAW!H6 | O6: =CHAIN_RAW!O6 | P6: =IFERROR(O6/N6,"") | Q6: =CHAIN_RAW!I6 | R6: =CHAIN_RAW!P6 | S6: =IFERROR(R6/Q6,"") | T6: =IFERROR((ABS(N6-O6)/MAX(1,(N6+O6)))*EXP(-ABS(E6-CONTROL!E5)/MAX(1,CONTROL!B8)),"") | U6: =IFERROR(IF(O6>N6,"SUPPORT (PE OI)","RESIST (CE OI)"),"") | V6: =IFERROR(IF(Q6>0,IF(R6>0,"BOTH_ADD","CE_ADD_PE_REDUCE"),IF(R6>0,"CE_REDUCE_PE_ADD","BOTH_REDUCE")),"") | W6: =IFERROR( (P6-1)*0.5 + (M6)*0.1 - (I6+J6)*0.05 + T6*0.4 ,"") | X6: =IFERROR(IF(ABS(F6)<0.01,"ATM/NEAR",""),"")
A7: =CHAIN_RAW!A7 | B7: =CHAIN_RAW!B7 | C7: =CHAIN_RAW!C7 | D7: =CHAIN_RAW!D7 | E7: =CHAIN_RAW!E7 | F7: =IFERROR((E7-D7)/D7,"") | G7: =IFERROR((CHAIN_RAW!K7+CHAIN_RAW!L7)/2,"") | H7: =IFERROR((CHAIN_RAW!R7+CHAIN_RAW!S7)/2,"") | I7: =IFERROR((CHAIN_RAW!L7-CHAIN_RAW!K7)/MAX(1E-9, G7),"") | J7: =IFERROR((CHAIN_RAW!S7-CHAIN_RAW!R7)/MAX(1E-9, H7),"") | K7: =CHAIN_RAW!G7 | L7: =CHAIN_RAW!N7 | M7: =IFERROR(L7-K7,"") | N7: =CHAIN_RAW!H7 | O7: =CHAIN_RAW!O7 | P7: =IFERROR(O7/N7,"") | Q7: =CHAIN_RAW!I7 | R7: =CHAIN_RAW!P7 | S7: =IFERROR(R7/Q7,"") | T7: =IFERROR((ABS(N7-O7)/MAX(1,(N7+O7)))*EXP(-ABS(E7-CONTROL!E5)/MAX(1,CONTROL!B8)),"") | U7: =IFERROR(IF(O7>N7,"SUPPORT (PE OI)","RESIST (CE OI)"),"") | V7: =IFERROR(IF(Q7>0,IF(R7>0,"BOTH_ADD","CE_ADD_PE_REDUCE"),IF(R7>0,"CE_REDUCE_PE_ADD","BOTH_REDUCE")),"") | W7: =IFERROR( (P7-1)*0.5 + (M7)*0.1 - (I7+J7)*0.05 + T7*0.4 ,"") | X7: =IFERROR(IF(ABS(F7)<0.01,"ATM/NEAR",""),"")
A8: =CHAIN_RAW!A8 | B8: =CHAIN_RAW!B8 | C8: =CHAIN_RAW!C8 | D8: =CHAIN_RAW!D8 | E8: =CHAIN_RAW!E8 | F8: =IFERROR((E8-D8)/D8,"") | G8: =IFERROR((CHAIN_RAW!K8+CHAIN_RAW!L8)/2,"") | H8: =IFERROR((CHAIN_RAW!R8+CHAIN_RAW!S8)/2,"") | I8: =IFERROR((CHAIN_RAW!L8-CHAIN_RAW!K8)/MAX(1E-9, G8),"") | J8: =IFERROR((CHAIN_RAW!S8-CHAIN_RAW!R8)/MAX(1E-9, H8),"") | K8: =CHAIN_RAW!G8 | L8: =CHAIN_RAW!N8 | M8: =IFERROR(L8-K8,"") | N8: =CHAIN_RAW!H8 | O8: =CHAIN_RAW!O8 | P8: =IFERROR(O8/N8,"") | Q8: =CHAIN_RAW!I8 | R8: =CHAIN_RAW!P8 | S8: =IFERROR(R8/Q8,"") | T8: =IFERROR((ABS(N8-O8)/MAX(1,(N8+O8)))*EXP(-ABS(E8-CONTROL!E5)/MAX(1,CONTROL!B8)),"") | U8: =IFERROR(IF(O8>N8,"SUPPORT (PE OI)","RESIST (CE OI)"),"") | V8: =IFERROR(IF(Q8>0,IF(R8>0,"BOTH_ADD","CE_ADD_PE_REDUCE"),IF(R8>0,"CE_REDUCE_PE_ADD","BOTH_REDUCE")),"") | W8: =IFERROR( (P8-1)*0.5 + (M8)*0.1 - (I8+J8)*0.05 + T8*0.4 ,"") | X8: =IFERROR(IF(ABS(F8)<0.01,"ATM/NEAR",""),"")
A9: =CHAIN_RAW!A9 | B9: =CHAIN_RAW!B9 | C9: =CHAIN_RAW!C9 | D9: =CHAIN_RAW!D9 | E9: =CHAIN_RAW!E9 | F9: =IFERROR((E9-D9)/D9,"") | G9: =IFERROR((CHAIN_RAW!K9+CHAIN_RAW!L9)/2,"") | H9: =IFERROR((CHAIN_RAW!R9+CHAIN_RAW!S9)/2,"") | I9: =IFERROR((CHAIN_RAW!L9-CHAIN_RAW!K9)/MAX(1E-9, G9),"") | J9: =IFERROR((CHAIN_RAW!S9-CHAIN_RAW!R9)/MAX(1E-9, H9),"") | K9: =CHAIN_RAW!G9 | L9: =CHAIN_RAW!N9 | M9: =IFERROR(L9-K9,"") | N9: =CHAIN_RAW!H9 | O9: =CHAIN_RAW!O9 | P9: =IFERROR(O9/N9,"") | Q9: =CHAIN_RAW!I9 | R9: =CHAIN_RAW!P9 | S9: =IFERROR(R9/Q9,"") | T9: =IFERROR((ABS(N9-O9)/MAX(1,(N9+O9)))*EXP(-ABS(E9-CONTROL!E5)/MAX(1,CONTROL!B8)),"") | U9: =IFERROR(IF(O9>N9,"SUPPORT (PE OI)","RESIST (CE OI)"),"") | V9: =IFERROR(IF(Q9>0,IF(R9>0,"BOTH_ADD","CE_ADD_PE_REDUCE"),IF(R9>0,"CE_REDUCE_PE_ADD","BOTH_REDUCE")),"") | W9: =IFERROR( (P9-1)*0.5 + (M9)*0.1 - (I9+J9)*0.05 + T9*0.4 ,"") | X9: =IFERROR(IF(ABS(F9)<0.01,"ATM/NEAR",""),"")
A10: =CHAIN_RAW!A10 | B10: =CHAIN_RAW!B10 | C10: =CHAIN_RAW!C10 | D10: =CHAIN_RAW!D10 | E10: =CHAIN_RAW!E10 | F10: =IFERROR((E10-D10)/D10,"") | G10: =IFERROR((CHAIN_RAW!K10+CHAIN_RAW!L10)/2,"") | H10: =IFERROR((CHAIN_RAW!R10+CHAIN_RAW!S10)/2,"") | I10: =IFERROR((CHAIN_RAW!L10-CHAIN_RAW!K10)/MAX(1E-9, G10),"") | J10: =IFERROR((CHAIN_RAW!S10-CHAIN_RAW!R10)/MAX(1E-9, H10),"") | K10: =CHAIN_RAW!G10 | L10: =CHAIN_RAW!N10 | M10: =IFERROR(L10-K10,"") | N10: =CHAIN_RAW!H10 | O10: =CHAIN_RAW!O10 | P10: =IFERROR(O10/N10,"") | Q10: =CHAIN_RAW!I10 | R10: =CHAIN_RAW!P10 | S10: =IFERROR(R10/Q10,"") | T10: =IFERROR((ABS(N10-O10)/MAX(1,(N10+O10)))*EXP(-ABS(E10-CONTROL!E5)/MAX(1,CONTROL!B8)),"") | U10: =IFERROR(IF(O10>N10,"SUPPORT (PE OI)","RESIST (CE OI)"),"") | V10: =IFERROR(IF(Q10>0,IF(R10>0,"BOTH_ADD","CE_ADD_PE_REDUCE"),IF(R10>0,"CE_REDUCE_PE_ADD","BOTH_REDUCE")),"") | W10: =IFERROR( (P10-1)*0.5 + (M10)*0.1 - (I10+J10)*0.05 + T10*0.4 ,"") | X10: =IFERROR(IF(ABS(F10)<0.01,"ATM/NEAR",""),"")
A11: =CHAIN_RAW!A11 | B11: =CHAIN_RAW!B11 | C11: =CHAIN_RAW!C11 | D11: =CHAIN_RAW!D11 | E11: =CHAIN_RAW!E11 | F11: =IFERROR((E11-D11)/D11,"") | G11: =IFERROR((CHAIN_RAW!K11+CHAIN_RAW!L11)/2,"") | H11: =IFERROR((CHAIN_RAW!R11+CHAIN_RAW!S11)/2,"") | I11: =IFERROR((CHAIN_RAW!L11-CHAIN_RAW!K11)/MAX(1E-9, G11),"") | J11: =IFERROR((CHAIN_RAW!S11-CHAIN_RAW!R11)/MAX(1E-9, H11),"") | K11: =CHAIN_RAW!G11 | L11: =CHAIN_RAW!N11 | M11: =IFERROR(L11-K11,"") | N11: =CHAIN_RAW!H11 | O11: =CHAIN_RAW!O11 | P11: =IFERROR(O11/N11,"") | Q11: =CHAIN_RAW!I11 | R11: =CHAIN_RAW!P11 | S11: =IFERROR(R11/Q11,"") | T11: =IFERROR((ABS(N11-O11)/MAX(1,(N11+O11)))*EXP(-ABS(E11-CONTROL!E5)/MAX(1,CONTROL!B8)),"") | U11: =IFERROR(IF(O11>N11,"SUPPORT (PE OI)","RESIST (CE OI)"),"") | V11: =IFERROR(IF(Q11>0,IF(R11>0,"BOTH_ADD","CE_ADD_PE_REDUCE"),IF(R11>0,"CE_REDUCE_PE_ADD","BOTH_REDUCE")),"") | W11: =IFERROR( (P11-1)*0.5 + (M11)*0.1 - (I11+J11)*0.05 + T11*0.4 ,"") | X11: =IFERROR(IF(ABS(F11)<0.01,"ATM/NEAR",""),"")
A12: =CHAIN_RAW!A12 | B12: =CHAIN_RAW!B12 | C12: =CHAIN_RAW!C12 | D12: =CHAIN_RAW!D12 | E12: =CHAIN_RAW!E12 | F12: =IFERROR((E12-D12)/D12,"") | G12: =IFERROR((CHAIN_RAW!K12+CHAIN_RAW!L12)/2,"") | H12: =IFERROR((CHAIN_RAW!R12+CHAIN_RAW!S12)/2,"") | I12: =IFERROR((CHAIN_RAW!L12-CHAIN_RAW!K12)/MAX(1E-9, G12),"") | J12: =IFERROR((CHAIN_RAW!S12-CHAIN_RAW!R12)/MAX(1E-9, H12),"") | K12: =CHAIN_RAW!G12 | L12: =CHAIN_RAW!N12 | M12: =IFERROR(L12-K12,"") | N12: =CHAIN_RAW!H12 | O12: =CHAIN_RAW!O12 | P12: =IFERROR(O12/N12,"") | Q12: =CHAIN_RAW!I12 | R12: =CHAIN_RAW!P12 | S12: =IFERROR(R12/Q12,"") | T12: =IFERROR((ABS(N12-O12)/MAX(1,(N12+O12)))*EXP(-ABS(E12-CONTROL!E5)/MAX(1,CONTROL!B8)),"") | U12: =IFERROR(IF(O12>N12,"SUPPORT (PE OI)","RESIST (CE OI)"),"") | V12: =IFERROR(IF(Q12>0,IF(R12>0,"BOTH_ADD","CE_ADD_PE_REDUCE"),IF(R12>0,"CE_REDUCE_PE_ADD","BOTH_REDUCE")),"") | W12: =IFERROR( (P12-1)*0.5 + (M12)*0.1 - (I12+J12)*0.05 + T12*0.4 ,"") | X12: =IFERROR(IF(ABS(F12)<0.01,"ATM/NEAR",""),"")
A13: =CHAIN_RAW!A13 | B13: =CHAIN_RAW!B13 | C13: =CHAIN_RAW!C13 | D13: =CHAIN_RAW!D13 | E13: =CHAIN_RAW!E13 | F13: =IFERROR((E13-D13)/D13,"") | G13: =IFERROR((CHAIN_RAW!K13+CHAIN_RAW!L13)/2,"") | H13: =IFERROR((CHAIN_RAW!R13+CHAIN_RAW!S13)/2,"") | I13: =IFERROR((CHAIN_RAW!L13-CHAIN_RAW!K13)/MAX(1E-9, G13),"") | J13: =IFERROR((CHAIN_RAW!S13-CHAIN_RAW!R13)/MAX(1E-9, H13),"") | K13: =CHAIN_RAW!G13 | L13: =CHAIN_RAW!N13 | M13: =IFERROR(L13-K13,"") | N13: =CHAIN_RAW!H13 | O13: =CHAIN_RAW!O13 | P13: =IFERROR(O13/N13,"") | Q13: =CHAIN_RAW!I13 | R13: =CHAIN_RAW!P13 | S13: =IFERROR(R13/Q13,"") | T13: =IFERROR((ABS(N13-O13)/MAX(1,(N13+O13)))*EXP(-ABS(E13-CONTROL!E5)/MAX(1,CONTROL!B8)),"") | U13: =IFERROR(IF(O13>N13,"SUPPORT (PE OI)","RESIST (CE OI)"),"") | V13: =IFERROR(IF(Q13>0,IF(R13>0,"BOTH_ADD","CE_ADD_PE_REDUCE"),IF(R13>0,"CE_REDUCE_PE_ADD","BOTH_REDUCE")),"") | W13: =IFERROR( (P13-1)*0.5 + (M13)*0.1 - (I13+J13)*0.05 + T13*0.4 ,"") | X13: =IFERROR(IF(ABS(F13)<0.01,"ATM/NEAR",""),"")
A14: =CHAIN_RAW!A14 | B14: =CHAIN_RAW!B14 | C14: =CHAIN_RAW!C14 | D14: =CHAIN_RAW!D14 | E14: =CHAIN_RAW!E14 | F14: =IFERROR((E14-D14)/D14,"") | G14: =IFERROR((CHAIN_RAW!K14+CHAIN_RAW!L14)/2,"") | H14: =IFERROR((CHAIN_RAW!R14+CHAIN_RAW!S14)/2,"") | I14: =IFERROR((CHAIN_RAW!L14-CHAIN_RAW!K14)/MAX(1E-9, G14),"") | J14: =IFERROR((CHAIN_RAW!S14-CHAIN_RAW!R14)/MAX(1E-9, H14),"") | K14: =CHAIN_RAW!G14 | L14: =CHAIN_RAW!N14 | M14: =IFERROR(L14-K14,"") | N14: =CHAIN_RAW!H14 | O14: =CHAIN_RAW!O14 | P14: =IFERROR(O14/N14,"") | Q14: =CHAIN_RAW!I14 | R14: =CHAIN_RAW!P14 | S14: =IFERROR(R14/Q14,"") | T14: =IFERROR((ABS(N14-O14)/MAX(1,(N14+O14)))*EXP(-ABS(E14-CONTROL!E5)/MAX(1,CONTROL!B8)),"") | U14: =IFERROR(IF(O14>N14,"SUPPORT (PE OI)","RESIST (CE OI)"),"") | V14: =IFERROR(IF(Q14>0,IF(R14>0,"BOTH_ADD","CE_ADD_PE_REDUCE"),IF(R14>0,"CE_REDUCE_PE_ADD","BOTH_REDUCE")),"") | W14: =IFERROR( (P14-1)*0.5 + (M14)*0.1 - (I14+J14)*0.05 + T14*0.4 ,"") | X14: =IFERROR(IF(ABS(F14)<0.01,"ATM/NEAR",""),"")
A15: =CHAIN_RAW!A15 | B15: =CHAIN_RAW!B15 | C15: =CHAIN_RAW!C15 | D15: =CHAIN_RAW!D15 | E15: =CHAIN_RAW!E15 | F15: =IFERROR((E15-D15)/D15,"") | G15: =IFERROR((CHAIN_RAW!K15+CHAIN_RAW!L15)/2,"") | H15: =IFERROR((CHAIN_RAW!R15+CHAIN_RAW!S15)/2,"") | I15: =IFERROR((CHAIN_RAW!L15-CHAIN_RAW!K15)/MAX(1E-9, G15),"") | J15: =IFERROR((CHAIN_RAW!S15-CHAIN_RAW!R15)/MAX(1E-9, H15),"") | K15: =CHAIN_RAW!G15 | L15: =CHAIN_RAW!N15 | M15: =IFERROR(L15-K15,"") | N15: =CHAIN_RAW!H15 | O15: =CHAIN_RAW!O15 | P15: =IFERROR(O15/N15,"") | Q15: =CHAIN_RAW!I15 | R15: =CHAIN_RAW!P15 | S15: =IFERROR(R15/Q15,"") | T15: =IFERROR((ABS(N15-O15)/MAX(1,(N15+O15)))*EXP(-ABS(E15-CONTROL!E5)/MAX(1,CONTROL!B8)),"") | U15: =IFERROR(IF(O15>N15,"SUPPORT (PE OI)","RESIST (CE OI)"),"") | V15: =IFERROR(IF(Q15>0,IF(R15>0,"BOTH_ADD","CE_ADD_PE_REDUCE"),IF(R15>0,"CE_REDUCE_PE_ADD","BOTH_REDUCE")),"") | W15: =IFERROR( (P15-1)*0.5 + (M15)*0.1 - (I15+J15)*0.05 + T15*0.4 ,"") | X15: =IFERROR(IF(ABS(F15)<0.01,"ATM/NEAR",""),"")
A16: =CHAIN_RAW!A16 | B16: =CHAIN_RAW!B16 | C16: =CHAIN_RAW!C16 | D16: =CHAIN_RAW!D16 | E16: =CHAIN_RAW!E16 | F16: =IFERROR((E16-D16)/D16,"") | G16: =IFERROR((CHAIN_RAW!K16+CHAIN_RAW!L16)/2,"") | H16: =IFERROR((CHAIN_RAW!R16+CHAIN_RAW!S16)/2,"") | I16: =IFERROR((CHAIN_RAW!L16-CHAIN_RAW!K16)/MAX(1E-9, G16),"") | J16: =IFERROR((CHAIN_RAW!S16-CHAIN_RAW!R16)/MAX(1E-9, H16),"") | K16: =CHAIN_RAW!G16 | L16: =CHAIN_RAW!N16 | M16: =IFERROR(L16-K16,"") | N16: =CHAIN_RAW!H16 | O16: =CHAIN_RAW!O16 | P16: =IFERROR(O16/N16,"") | Q16: =CHAIN_RAW!I16 | R16: =CHAIN_RAW!P16 | S16: =IFERROR(R16/Q16,"") | T16: =IFERROR((ABS(N16-O16)/MAX(1,(N16+O16)))*EXP(-ABS(E16-CONTROL!E5)/MAX(1,CONTROL!B8)),"") | U16: =IFERROR(IF(O16>N16,"SUPPORT (PE OI)","RESIST (CE OI)"),"") | V16: =IFERROR(IF(Q16>0,IF(R16>0,"BOTH_ADD","CE_ADD_PE_REDUCE"),IF(R16>0,"CE_REDUCE_PE_ADD","BOTH_REDUCE")),"") | W16: =IFERROR( (P16-1)*0.5 + (M16)*0.1 - (I16+J16)*0.05 + T16*0.4 ,"") | X16: =IFERROR(IF(ABS(F16)<0.01,"ATM/NEAR",""),"")
A17: =CHAIN_RAW!A17 | B17: =CHAIN_RAW!B17 | C17: =CHAIN_RAW!C17 | D17: =CHAIN_RAW!D17 | E17: =CHAIN_RAW!E17 | F17: =IFERROR((E17-D17)/D17,"") | G17: =IFERROR((CHAIN_RAW!K17+CHAIN_RAW!L17)/2,"") | H17: =IFERROR((CHAIN_RAW!R17+CHAIN_RAW!S17)/2,"") | I17: =IFERROR((CHAIN_RAW!L17-CHAIN_RAW!K17)/MAX(1E-9, G17),"") | J17: =IFERROR((CHAIN_RAW!S17-CHAIN_RAW!R17)/MAX(1E-9, H17),"") | K17: =CHAIN_RAW!G17 | L17: =CHAIN_RAW!N17 | M17: =IFERROR(L17-K17,"") | N17: =CHAIN_RAW!H17 | O17: =CHAIN_RAW!O17 | P17: =IFERROR(O17/N17,"") | Q17: =CHAIN_RAW!I17 | R17: =CHAIN_RAW!P17 | S17: =IFERROR(R17/Q17,"") | T17: =IFERROR((ABS(N17-O17)/MAX(1,(N17+O17)))*EXP(-ABS(E17-CONTROL!E5)/MAX(1,CONTROL!B8)),"") | U17: =IFERROR(IF(O17>N17,"SUPPORT (PE OI)","RESIST (CE OI)"),"") | V17: =IFERROR(IF(Q17>0,IF(R17>0,"BOTH_ADD","CE_ADD_PE_REDUCE"),IF(R17>0,"CE_REDUCE_PE_ADD","BOTH_REDUCE")),"") | W17: =IFERROR( (P17-1)*0.5 + (M17)*0.1 - (I17+J17)*0.05 + T17*0.4 ,"") | X17: =IFERROR(IF(ABS(F17)<0.01,"ATM/NEAR",""),"")
A18: =CHAIN_RAW!A18 | B18: =CHAIN_RAW!B18 | C18: =CHAIN_RAW!C18 | D18: =CHAIN_RAW!D18 | E18: =CHAIN_RAW!E18 | F18: =IFERROR((E18-D18)/D18,"") | G18: =IFERROR((CHAIN_RAW!K18+CHAIN_RAW!L18)/2,"") | H18: =IFERROR((CHAIN_RAW!R18+CHAIN_RAW!S18)/2,"") | I18: =IFERROR((CHAIN_RAW!L18-CHAIN_RAW!K18)/MAX(1E-9, G18),"") | J18: =IFERROR((CHAIN_RAW!S18-CHAIN_RAW!R18)/MAX(1E-9, H18),"") | K18: =CHAIN_RAW!G18 | L18: =CHAIN_RAW!N18 | M18: =IFERROR(L18-K18,"") | N18: =CHAIN_RAW!H18 | O18: =CHAIN_RAW!O18 | P18: =IFERROR(O18/N18,"") | Q18: =CHAIN_RAW!I18 | R18: =CHAIN_RAW!P18 | S18: =IFERROR(R18/Q18,"") | T18: =IFERROR((ABS(N18-O18)/MAX(1,(N18+O18)))*EXP(-ABS(E18-CONTROL!E5)/MAX(1,CONTROL!B8)),"") | U18: =IFERROR(IF(O18>N18,"SUPPORT (PE OI)","RESIST (CE OI)"),"") | V18: =IFERROR(IF(Q18>0,IF(R18>0,"BOTH_ADD","CE_ADD_PE_REDUCE"),IF(R18>0,"CE_REDUCE_PE_ADD","BOTH_REDUCE")),"") | W18: =IFERROR( (P18-1)*0.5 + (M18)*0.1 - (I18+J18)*0.05 + T18*0.4 ,"") | X18: =IFERROR(IF(ABS(F18)<0.01,"ATM/NEAR",""),"")
A19: =CHAIN_RAW!A19 | B19: =CHAIN_RAW!B19 | C19: =CHAIN_RAW!C19 | D19: =CHAIN_RAW!D19 | E19: =CHAIN_RAW!E19 | F19: =IFERROR((E19-D19)/D19,"") | G19: =IFERROR((CHAIN_RAW!K19+CHAIN_RAW!L19)/2,"") | H19: =IFERROR((CHAIN_RAW!R19+CHAIN_RAW!S19)/2,"") | I19: =IFERROR((CHAIN_RAW!L19-CHAIN_RAW!K19)/MAX(1E-9, G19),"") | J19: =IFERROR((CHAIN_RAW!S19-CHAIN_RAW!R19)/MAX(1E-9, H19),"") | K19: =CHAIN_RAW!G19 | L19: =CHAIN_RAW!N19 | M19: =IFERROR(L19-K19,"") | N19: =CHAIN_RAW!H19 | O19: =CHAIN_RAW!O19 | P19: =IFERROR(O19/N19,"") | Q19: =CHAIN_RAW!I19 | R19: =CHAIN_RAW!P19 | S19: =IFERROR(R19/Q19,"") | T19: =IFERROR((ABS(N19-O19)/MAX(1,(N19+O19)))*EXP(-ABS(E19-CONTROL!E5)/MAX(1,CONTROL!B8)),"") | U19: =IFERROR(IF(O19>N19,"SUPPORT (PE OI)","RESIST (CE OI)"),"") | V19: =IFERROR(IF(Q19>0,IF(R19>0,"BOTH_ADD","CE_ADD_PE_REDUCE"),IF(R19>0,"CE_REDUCE_PE_ADD","BOTH_REDUCE")),"") | W19: =IFERROR( (P19-1)*0.5 + (M19)*0.1 - (I19+J19)*0.05 + T19*0.4 ,"") | X19: =IFERROR(IF(ABS(F19)<0.01,"ATM/NEAR",""),"")
A20: =CHAIN_RAW!A20 | B20: =CHAIN_RAW!B20 | C20: =CHAIN_RAW!C20 | D20: =CHAIN_RAW!D20 | E20: =CHAIN_RAW!E20 | F20: =IFERROR((E20-D20)/D20,"") | G20: =IFERROR((CHAIN_RAW!K20+CHAIN_RAW!L20)/2,"") | H20: =IFERROR((CHAIN_RAW!R20+CHAIN_RAW!S20)/2,"") | I20: =IFERROR((CHAIN_RAW!L20-CHAIN_RAW!K20)/MAX(1E-9, G20),"") | J20: =IFERROR((CHAIN_RAW!S20-CHAIN_RAW!R20)/MAX(1E-9, H20),"") | K20: =CHAIN_RAW!G20 | L20: =CHAIN_RAW!N20 | M20: =IFERROR(L20-K20,"") | N20: =CHAIN_RAW!H20 | O20: =CHAIN_RAW!O20 | P20: =IFERROR(O20/N20,"") | Q20: =CHAIN_RAW!I20 | R20: =CHAIN_RAW!P20 | S20: =IFERROR(R20/Q20,"") | T20: =IFERROR((ABS(N20-O20)/MAX(1,(N20+O20)))*EXP(-ABS(E20-CONTROL!E5)/MAX(1,CONTROL!B8)),"") | U20: =IFERROR(IF(O20>N20,"SUPPORT (PE OI)","RESIST (CE OI)"),"") | V20: =IFERROR(IF(Q20>0,IF(R20>0,"BOTH_ADD","CE_ADD_PE_REDUCE"),IF(R20>0,"CE_REDUCE_PE_ADD","BOTH_REDUCE")),"") | W20: =IFERROR( (P20-1)*0.5 + (M20)*0.1 - (I20+J20)*0.05 + T20*0.4 ,"") | X20: =IFERROR(IF(ABS(F20)<0.01,"ATM/NEAR",""),"")
A21: =CHAIN_RAW!A21 | B21: =CHAIN_RAW!B21 | C21: =CHAIN_RAW!C21 | D21: =CHAIN_RAW!D21 | E21: =CHAIN_RAW!E21 | F21: =IFERROR((E21-D21)/D21,"") | G21: =IFERROR((CHAIN_RAW!K21+CHAIN_RAW!L21)/2,"") | H21: =IFERROR((CHAIN_RAW!R21+CHAIN_RAW!S21)/2,"") | I21: =IFERROR((CHAIN_RAW!L21-CHAIN_RAW!K21)/MAX(1E-9, G21),"") | J21: =IFERROR((CHAIN_RAW!S21-CHAIN_RAW!R21)/MAX(1E-9, H21),"") | K21: =CHAIN_RAW!G21 | L21: =CHAIN_RAW!N21 | M21: =IFERROR(L21-K21,"") | N21: =CHAIN_RAW!H21 | O21: =CHAIN_RAW!O21 | P21: =IFERROR(O21/N21,"") | Q21: =CHAIN_RAW!I21 | R21: =CHAIN_RAW!P21 | S21: =IFERROR(R21/Q21,"") | T21: =IFERROR((ABS(N21-O21)/MAX(1,(N21+O21)))*EXP(-ABS(E21-CONTROL!E5)/MAX(1,CONTROL!B8)),"") | U21: =IFERROR(IF(O21>N21,"SUPPORT (PE OI)","RESIST (CE OI)"),"") | V21: =IFERROR(IF(Q21>0,IF(R21>0,"BOTH_ADD","CE_ADD_PE_REDUCE"),IF(R21>0,"CE_REDUCE_PE_ADD","BOTH_REDUCE")),"") | W21: =IFERROR( (P21-1)*0.5 + (M21)*0.1 - (I21+J21)*0.05 + T21*0.4 ,"") | X21: =IFERROR(IF(ABS(F21)<0.01,"ATM/NEAR",""),"")
A22: =CHAIN_RAW!A22 | B22: =CHAIN_RAW!B22 | C22: =CHAIN_RAW!C22 | D22: =CHAIN_RAW!D22 | E22: =CHAIN_RAW!E22 | F22: =IFERROR((E22-D22)/D22,"") | G22: =IFERROR((CHAIN_RAW!K22+CHAIN_RAW!L22)/2,"") | H22: =IFERROR((CHAIN_RAW!R22+CHAIN_RAW!S22)/2,"") | I22: =IFERROR((CHAIN_RAW!L22-CHAIN_RAW!K22)/MAX(1E-9, G22),"") | J22: =IFERROR((CHAIN_RAW!S22-CHAIN_RAW!R22)/MAX(1E-9, H22),"") | K22: =CHAIN_RAW!G22 | L22: =CHAIN_RAW!N22 | M22: =IFERROR(L22-K22,"") | N22: =CHAIN_RAW!H22 | O22: =CHAIN_RAW!O22 | P22: =IFERROR(O22/N22,"") | Q22: =CHAIN_RAW!I22 | R22: =CHAIN_RAW!P22 | S22: =IFERROR(R22/Q22,"") | T22: =IFERROR((ABS(N22-O22)/MAX(1,(N22+O22)))*EXP(-ABS(E22-CONTROL!E5)/MAX(1,CONTROL!B8)),"") | U22: =IFERROR(IF(O22>N22,"SUPPORT (PE OI)","RESIST (CE OI)"),"") | V22: =IFERROR(IF(Q22>0,IF(R22>0,"BOTH_ADD","CE_ADD_PE_REDUCE"),IF(R22>0,"CE_REDUCE_PE_ADD","BOTH_REDUCE")),"") | W22: =IFERROR( (P22-1)*0.5 + (M22)*0.1 - (I22+J22)*0.05 + T22*0.4 ,"") | X22: =IFERROR(IF(ABS(F22)<0.01,"ATM/NEAR",""),"")
A23: =CHAIN_RAW!A23 | B23: =CHAIN_RAW!B23 | C23: =CHAIN_RAW!C23 | D23: =CHAIN_RAW!D23 | E23: =CHAIN_RAW!E23 | F23: =IFERROR((E23-D23)/D23,"") | G23: =IFERROR((CHAIN_RAW!K23+CHAIN_RAW!L23)/2,"") | H23: =IFERROR((CHAIN_RAW!R23+CHAIN_RAW!S23)/2,"") | I23: =IFERROR((CHAIN_RAW!L23-CHAIN_RAW!K23)/MAX(1E-9, G23),"") | J23: =IFERROR((CHAIN_RAW!S23-CHAIN_RAW!R23)/MAX(1E-9, H23),"") | K23: =CHAIN_RAW!G23 | L23: =CHAIN_RAW!N23 | M23: =IFERROR(L23-K23,"") | N23: =CHAIN_RAW!H23 | O23: =CHAIN_RAW!O23 | P23: =IFERROR(O23/N23,"") | Q23: =CHAIN_RAW!I23 | R23: =CHAIN_RAW!P23 | S23: =IFERROR(R23/Q23,"") | T23: =IFERROR((ABS(N23-O23)/MAX(1,(N23+O23)))*EXP(-ABS(E23-CONTROL!E5)/MAX(1,CONTROL!B8)),"") | U23: =IFERROR(IF(O23>N23,"SUPPORT (PE OI)","RESIST (CE OI)"),"") | V23: =IFERROR(IF(Q23>0,IF(R23>0,"BOTH_ADD","CE_ADD_PE_REDUCE"),IF(R23>0,"CE_REDUCE_PE_ADD","BOTH_REDUCE")),"") | W23: =IFERROR( (P23-1)*0.5 + (M23)*0.1 - (I23+J23)*0.05 + T23*0.4 ,"") | X23: =IFERROR(IF(ABS(F23)<0.01,"ATM/NEAR",""),"")
A24: =CHAIN_RAW!A24 | B24: =CHAIN_RAW!B24 | C24: =CHAIN_RAW!C24 | D24: =CHAIN_RAW!D24 | E24: =CHAIN_RAW!E24 | F24: =IFERROR((E24-D24)/D24,"") | G24: =IFERROR((CHAIN_RAW!K24+CHAIN_RAW!L24)/2,"") | H24: =IFERROR((CHAIN_RAW!R24+CHAIN_RAW!S24)/2,"") | I24: =IFERROR((CHAIN_RAW!L24-CHAIN_RAW!K24)/MAX(1E-9, G24),"") | J24: =IFERROR((CHAIN_RAW!S24-CHAIN_RAW!R24)/MAX(1E-9, H24),"") | K24: =CHAIN_RAW!G24 | L24: =CHAIN_RAW!N24 | M24: =IFERROR(L24-K24,"") | N24: =CHAIN_RAW!H24 | O24: =CHAIN_RAW!O24 | P24: =IFERROR(O24/N24,"") | Q24: =CHAIN_RAW!I24 | R24: =CHAIN_RAW!P24 | S24: =IFERROR(R24/Q24,"") | T24: =IFERROR((ABS(N24-O24)/MAX(1,(N24+O24)))*EXP(-ABS(E24-CONTROL!E5)/MAX(1,CONTROL!B8)),"") | U24: =IFERROR(IF(O24>N24,"SUPPORT (PE OI)","RESIST (CE OI)"),"") | V24: =IFERROR(IF(Q24>0,IF(R24>0,"BOTH_ADD","CE_ADD_PE_REDUCE"),IF(R24>0,"CE_REDUCE_PE_ADD","BOTH_REDUCE")),"") | W24: =IFERROR( (P24-1)*0.5 + (M24)*0.1 - (I24+J24)*0.05 + T24*0.4 ,"") | X24: =IFERROR(IF(ABS(F24)<0.01,"ATM/NEAR",""),"")
A25: =CHAIN_RAW!A25 | B25: =CHAIN_RAW!B25 | C25: =CHAIN_RAW!C25 | D25: =CHAIN_RAW!D25 | E25: =CHAIN_RAW!E25 | F25: =IFERROR((E25-D25)/D25,"") | G25: =IFERROR((CHAIN_RAW!K25+CHAIN_RAW!L25)/2,"") | H25: =IFERROR((CHAIN_RAW!R25+CHAIN_RAW!S25)/2,"") | I25: =IFERROR((CHAIN_RAW!L25-CHAIN_RAW!K25)/MAX(1E-9, G25),"") | J25: =IFERROR((CHAIN_RAW!S25-CHAIN_RAW!R25)/MAX(1E-9, H25),"") | K25: =CHAIN_RAW!G25 | L25: =CHAIN_RAW!N25 | M25: =IFERROR(L25-K25,"") | N25: =CHAIN_RAW!H25 | O25: =CHAIN_RAW!O25 | P25: =IFERROR(O25/N25,"") | Q25: =CHAIN_RAW!I25 | R25: =CHAIN_RAW!P25 | S25: =IFERROR(R25/Q25,"") | T25: =IFERROR((ABS(N25-O25)/MAX(1,(N25+O25)))*EXP(-ABS(E25-CONTROL!E5)/MAX(1,CONTROL!B8)),"") | U25: =IFERROR(IF(O25>N25,"SUPPORT (PE OI)","RESIST (CE OI)"),"") | V25: =IFERROR(IF(Q25>0,IF(R25>0,"BOTH_ADD","CE_ADD_PE_REDUCE"),IF(R25>0,"CE_REDUCE_PE_ADD","BOTH_REDUCE")),"") | W25: =IFERROR( (P25-1)*0.5 + (M25)*0.1 - (I25+J25)*0.05 + T25*0.4 ,"") | X25: =IFERROR(IF(ABS(F25)<0.01,"ATM/NEAR",""),"")
A26: =CHAIN_RAW!A26 | B26: =CHAIN_RAW!B26 | C26: =CHAIN_RAW!C26 | D26: =CHAIN_RAW!D26 | E26: =CHAIN_RAW!E26 | F26: =IFERROR((E26-D26)/D26,"") | G26: =IFERROR((CHAIN_RAW!K26+CHAIN_RAW!L26)/2,"") | H26: =IFERROR((CHAIN_RAW!R26+CHAIN_RAW!S26)/2,"") | I26: =IFERROR((CHAIN_RAW!L26-CHAIN_RAW!K26)/MAX(1E-9, G26),"") | J26: =IFERROR((CHAIN_RAW!S26-CHAIN_RAW!R26)/MAX(1E-9, H26),"") | K26: =CHAIN_RAW!G26 | L26: =CHAIN_RAW!N26 | M26: =IFERROR(L26-K26,"") | N26: =CHAIN_RAW!H26 | O26: =CHAIN_RAW!O26 | P26: =IFERROR(O26/N26,"") | Q26: =CHAIN_RAW!I26 | R26: =CHAIN_RAW!P26 | S26: =IFERROR(R26/Q26,"") | T26: =IFERROR((ABS(N26-O26)/MAX(1,(N26+O26)))*EXP(-ABS(E26-CONTROL!E5)/MAX(1,CONTROL!B8)),"") | U26: =IFERROR(IF(O26>N26,"SUPPORT (PE OI)","RESIST (CE OI)"),"") | V26: =IFERROR(IF(Q26>0,IF(R26>0,"BOTH_ADD","CE_ADD_PE_REDUCE"),IF(R26>0,"CE_REDUCE_PE_ADD","BOTH_REDUCE")),"") | W26: =IFERROR( (P26-1)*0.5 + (M26)*0.1 - (I26+J26)*0.05 + T26*0.4 ,"") | X26: =IFERROR(IF(ABS(F26)<0.01,"ATM/NEAR",""),"")
A27: =CHAIN_RAW!A27 | B27: =CHAIN_RAW!B27 | C27: =CHAIN_RAW!C27 | D27: =CHAIN_RAW!D27 | E27: =CHAIN_RAW!E27 | F27: =IFERROR((E27-D27)/D27,"") | G27: =IFERROR((CHAIN_RAW!K27+CHAIN_RAW!L27)/2,"") | H27: =IFERROR((CHAIN_RAW!R27+CHAIN_RAW!S27)/2,"") | I27: =IFERROR((CHAIN_RAW!L27-CHAIN_RAW!K27)/MAX(1E-9, G27),"") | J27: =IFERROR((CHAIN_RAW!S27-CHAIN_RAW!R27)/MAX(1E-9, H27),"") | K27: =CHAIN_RAW!G27 | L27: =CHAIN_RAW!N27 | M27: =IFERROR(L27-K27,"") | N27: =CHAIN_RAW!H27 | O27: =CHAIN_RAW!O27 | P27: =IFERROR(O27/N27,"") | Q27: =CHAIN_RAW!I27 | R27: =CHAIN_RAW!P27 | S27: =IFERROR(R27/Q27,"") | T27: =IFERROR((ABS(N27-O27)/MAX(1,(N27+O27)))*EXP(-ABS(E27-CONTROL!E5)/MAX(1,CONTROL!B8)),"") | U27: =IFERROR(IF(O27>N27,"SUPPORT (PE OI)","RESIST (CE OI)"),"") | V27: =IFERROR(IF(Q27>0,IF(R27>0,"BOTH_ADD","CE_ADD_PE_REDUCE"),IF(R27>0,"CE_REDUCE_PE_ADD","BOTH_REDUCE")),"") | W27: =IFERROR( (P27-1)*0.5 + (M27)*0.1 - (I27+J27)*0.05 + T27*0.4 ,"") | X27: =IFERROR(IF(ABS(F27)<0.01,"ATM/NEAR",""),"")
A28: =CHAIN_RAW!A28 | B28: =CHAIN_RAW!B28 | C28: =CHAIN_RAW!C28 | D28: =CHAIN_RAW!D28 | E28: =CHAIN_RAW!E28 | F28: =IFERROR((E28-D28)/D28,"") | G28: =IFERROR((CHAIN_RAW!K28+CHAIN_RAW!L28)/2,"") | H28: =IFERROR((CHAIN_RAW!R28+CHAIN_RAW!S28)/2,"") | I28: =IFERROR((CHAIN_RAW!L28-CHAIN_RAW!K28)/MAX(1E-9, G28),"") | J28: =IFERROR((CHAIN_RAW!S28-CHAIN_RAW!R28)/MAX(1E-9, H28),"") | K28: =CHAIN_RAW!G28 | L28: =CHAIN_RAW!N28 | M28: =IFERROR(L28-K28,"") | N28: =CHAIN_RAW!H28 | O28: =CHAIN_RAW!O28 | P28: =IFERROR(O28/N28,"") | Q28: =CHAIN_RAW!I28 | R28: =CHAIN_RAW!P28 | S28: =IFERROR(R28/Q28,"") | T28: =IFERROR((ABS(N28-O28)/MAX(1,(N28+O28)))*EXP(-ABS(E28-CONTROL!E5)/MAX(1,CONTROL!B8)),"") | U28: =IFERROR(IF(O28>N28,"SUPPORT (PE OI)","RESIST (CE OI)"),"") | V28: =IFERROR(IF(Q28>0,IF(R28>0,"BOTH_ADD","CE_ADD_PE_REDUCE"),IF(R28>0,"CE_REDUCE_PE_ADD","BOTH_REDUCE")),"") | W28: =IFERROR( (P28-1)*0.5 + (M28)*0.1 - (I28+J28)*0.05 + T28*0.4 ,"") | X28: =IFERROR(IF(ABS(F28)<0.01,"ATM/NEAR",""),"")
A29: =CHAIN_RAW!A29 | B29: =CHAIN_RAW!B29 | C29: =CHAIN_RAW!C29 | D29: =CHAIN_RAW!D29 | E29: =CHAIN_RAW!E29 | F29: =IFERROR((E29-D29)/D29,"") | G29: =IFERROR((CHAIN_RAW!K29+CHAIN_RAW!L29)/2,"") | H29: =IFERROR((CHAIN_RAW!R29+CHAIN_RAW!S29)/2,"") | I29: =IFERROR((CHAIN_RAW!L29-CHAIN_RAW!K29)/MAX(1E-9, G29),"") | J29: =IFERROR((CHAIN_RAW!S29-CHAIN_RAW!R29)/MAX(1E-9, H29),"") | K29: =CHAIN_RAW!G29 | L29: =CHAIN_RAW!N29 | M29: =IFERROR(L29-K29,"") | N29: =CHAIN_RAW!H29 | O29: =CHAIN_RAW!O29 | P29: =IFERROR(O29/N29,"") | Q29: =CHAIN_RAW!I29 | R29: =CHAIN_RAW!P29 | S29: =IFERROR(R29/Q29,"") | T29: =IFERROR((ABS(N29-O29)/MAX(1,(N29+O29)))*EXP(-ABS(E29-CONTROL!E5)/MAX(1,CONTROL!B8)),"") | U29: =IFERROR(IF(O29>N29,"SUPPORT (PE OI)","RESIST (CE OI)"),"") | V29: =IFERROR(IF(Q29>0,IF(R29>0,"BOTH_ADD","CE_ADD_PE_REDUCE"),IF(R29>0,"CE_REDUCE_PE_ADD","BOTH_REDUCE")),"") | W29: =IFERROR( (P29-1)*0.5 + (M29)*0.1 - (I29+J29)*0.05 + T29*0.4 ,"") | X29: =IFERROR(IF(ABS(F29)<0.01,"ATM/NEAR",""),"")
A30: =CHAIN_RAW!A30 | B30: =CHAIN_RAW!B30 | C30: =CHAIN_RAW!C30 | D30: =CHAIN_RAW!D30 | E30: =CHAIN_RAW!E30 | F30: =IFERROR((E30-D30)/D30,"") | G30: =IFERROR((CHAIN_RAW!K30+CHAIN_RAW!L30)/2,"") | H30: =IFERROR((CHAIN_RAW!R30+CHAIN_RAW!S30)/2,"") | I30: =IFERROR((CHAIN_RAW!L30-CHAIN_RAW!K30)/MAX(1E-9, G30),"") | J30: =IFERROR((CHAIN_RAW!S30-CHAIN_RAW!R30)/MAX(1E-9, H30),"") | K30: =CHAIN_RAW!G30 | L30: =CHAIN_RAW!N30 | M30: =IFERROR(L30-K30,"") | N30: =CHAIN_RAW!H30 | O30: =CHAIN_RAW!O30 | P30: =IFERROR(O30/N30,"") | Q30: =CHAIN_RAW!I30 | R30: =CHAIN_RAW!P30 | S30: =IFERROR(R30/Q30,"") | T30: =IFERROR((ABS(N30-O30)/MAX(1,(N30+O30)))*EXP(-ABS(E30-CONTROL!E5)/MAX(1,CONTROL!B8)),"") | U30: =IFERROR(IF(O30>N30,"SUPPORT (PE OI)","RESIST (CE OI)"),"") | V30: =IFERROR(IF(Q30>0,IF(R30>0,"BOTH_ADD","CE_ADD_PE_REDUCE"),IF(R30>0,"CE_REDUCE_PE_ADD","BOTH_REDUCE")),"") | W30: =IFERROR( (P30-1)*0.5 + (M30)*0.1 - (I30+J30)*0.05 + T30*0.4 ,"") | X30: =IFERROR(IF(ABS(F30)<0.01,"ATM/NEAR",""),"")
A31: =CHAIN_RAW!A31 | B31: =CHAIN_RAW!B31 | C31: =CHAIN_RAW!C31 | D31: =CHAIN_RAW!D31 | E31: =CHAIN_RAW!E31 | F31: =IFERROR((E31-D31)/D31,"") | G31: =IFERROR((CHAIN_RAW!K31+CHAIN_RAW!L31)/2,"") | H31: =IFERROR((CHAIN_RAW!R31+CHAIN_RAW!S31)/2,"") | I31: =IFERROR((CHAIN_RAW!L31-CHAIN_RAW!K31)/MAX(1E-9, G31),"") | J31: =IFERROR((CHAIN_RAW!S31-CHAIN_RAW!R31)/MAX(1E-9, H31),"") | K31: =CHAIN_RAW!G31 | L31: =CHAIN_RAW!N31 | M31: =IFERROR(L31-K31,"") | N31: =CHAIN_RAW!H31 | O31: =CHAIN_RAW!O31 | P31: =IFERROR(O31/N31,"") | Q31: =CHAIN_RAW!I31 | R31: =CHAIN_RAW!P31 | S31: =IFERROR(R31/Q31,"") | T31: =IFERROR((ABS(N31-O31)/MAX(1,(N31+O31)))*EXP(-ABS(E31-CONTROL!E5)/MAX(1,CONTROL!B8)),"") | U31: =IFERROR(IF(O31>N31,"SUPPORT (PE OI)","RESIST (CE OI)"),"") | V31: =IFERROR(IF(Q31>0,IF(R31>0,"BOTH_ADD","CE_ADD_PE_REDUCE"),IF(R31>0,"CE_REDUCE_PE_ADD","BOTH_REDUCE")),"") | W31: =IFERROR( (P31-1)*0.5 + (M31)*0.1 - (I31+J31)*0.05 + T31*0.4 ,"") | X31: =IFERROR(IF(ABS(F31)<0.01,"ATM/NEAR",""),"")
A32: =CHAIN_RAW!A32 | B32: =CHAIN_RAW!B32 | C32: =CHAIN_RAW!C32 | D32: =CHAIN_RAW!D32 | E32: =CHAIN_RAW!E32 | F32: =IFERROR((E32-D32)/D32,"") | G32: =IFERROR((CHAIN_RAW!K32+CHAIN_RAW!L32)/2,"") | H32: =IFERROR((CHAIN_RAW!R32+CHAIN_RAW!S32)/2,"") | I32: =IFERROR((CHAIN_RAW!L32-CHAIN_RAW!K32)/MAX(1E-9, G32),"") | J32: =IFERROR((CHAIN_RAW!S32-CHAIN_RAW!R32)/MAX(1E-9, H32),"") | K32: =CHAIN_RAW!G32 | L32: =CHAIN_RAW!N32 | M32: =IFERROR(L32-K32,"") | N32: =CHAIN_RAW!H32 | O32: =CHAIN_RAW!O32 | P32: =IFERROR(O32/N32,"") | Q32: =CHAIN_RAW!I32 | R32: =CHAIN_RAW!P32 | S32: =IFERROR(R32/Q32,"") | T32: =IFERROR((ABS(N32-O32)/MAX(1,(N32+O32)))*EXP(-ABS(E32-CONTROL!E5)/MAX(1,CONTROL!B8)),"") | U32: =IFERROR(IF(O32>N32,"SUPPORT (PE OI)","RESIST (CE OI)"),"") | V32: =IFERROR(IF(Q32>0,IF(R32>0,"BOTH_ADD","CE_ADD_PE_REDUCE"),IF(R32>0,"CE_REDUCE_PE_ADD","BOTH_REDUCE")),"") | W32: =IFERROR( (P32-1)*0.5 + (M32)*0.1 - (I32+J32)*0.05 + T32*0.4 ,"") | X32: =IFERROR(IF(ABS(F32)<0.01,"ATM/NEAR",""),"")
A33: =CHAIN_RAW!A33 | B33: =CHAIN_RAW!B33 | C33: =CHAIN_RAW!C33 | D33: =CHAIN_RAW!D33 | E33: =CHAIN_RAW!E33 | F33: =IFERROR((E33-D33)/D33,"") | G33: =IFERROR((CHAIN_RAW!K33+CHAIN_RAW!L33)/2,"") | H33: =IFERROR((CHAIN_RAW!R33+CHAIN_RAW!S33)/2,"") | I33: =IFERROR((CHAIN_RAW!L33-CHAIN_RAW!K33)/MAX(1E-9, G33),"") | J33: =IFERROR((CHAIN_RAW!S33-CHAIN_RAW!R33)/MAX(1E-9, H33),"") | K33: =CHAIN_RAW!G33 | L33: =CHAIN_RAW!N33 | M33: =IFERROR(L33-K33,"") | N33: =CHAIN_RAW!H33 | O33: =CHAIN_RAW!O33 | P33: =IFERROR(O33/N33,"") | Q33: =CHAIN_RAW!I33 | R33: =CHAIN_RAW!P33 | S33: =IFERROR(R33/Q33,"") | T33: =IFERROR((ABS(N33-O33)/MAX(1,(N33+O33)))*EXP(-ABS(E33-CONTROL!E5)/MAX(1,CONTROL!B8)),"") | U33: =IFERROR(IF(O33>N33,"SUPPORT (PE OI)","RESIST (CE OI)"),"") | V33: =IFERROR(IF(Q33>0,IF(R33>0,"BOTH_ADD","CE_ADD_PE_REDUCE"),IF(R33>0,"CE_REDUCE_PE_ADD","BOTH_REDUCE")),"") | W33: =IFERROR( (P33-1)*0.5 + (M33)*0.1 - (I33+J33)*0.05 + T33*0.4 ,"") | X33: =IFERROR(IF(ABS(F33)<0.01,"ATM/NEAR",""),"")
A34: =CHAIN_RAW!A34 | B34: =CHAIN_RAW!B34 | C34: =CHAIN_RAW!C34 | D34: =CHAIN_RAW!D34 | E34: =CHAIN_RAW!E34 | F34: =IFERROR((E34-D34)/D34,"") | G34: =IFERROR((CHAIN_RAW!K34+CHAIN_RAW!L34)/2,"") | H34: =IFERROR((CHAIN_RAW!R34+CHAIN_RAW!S34)/2,"") | I34: =IFERROR((CHAIN_RAW!L34-CHAIN_RAW!K34)/MAX(1E-9, G34),"") | J34: =IFERROR((CHAIN_RAW!S34-CHAIN_RAW!R34)/MAX(1E-9, H34),"") | K34: =CHAIN_RAW!G34 | L34: =CHAIN_RAW!N34 | M34: =IFERROR(L34-K34,"") | N34: =CHAIN_RAW!H34 | O34: =CHAIN_RAW!O34 | P34: =IFERROR(O34/N34,"") | Q34: =CHAIN_RAW!I34 | R34: =CHAIN_RAW!P34 | S34: =IFERROR(R34/Q34,"") | T34: =IFERROR((ABS(N34-O34)/MAX(1,(N34+O34)))*EXP(-ABS(E34-CONTROL!E5)/MAX(1,CONTROL!B8)),"") | U34: =IFERROR(IF(O34>N34,"SUPPORT (PE OI)","RESIST (CE OI)"),"") | V34: =IFERROR(IF(Q34>0,IF(R34>0,"BOTH_ADD","CE_ADD_PE_REDUCE"),IF(R34>0,"CE_REDUCE_PE_ADD","BOTH_REDUCE")),"") | W34: =IFERROR( (P34-1)*0.5 + (M34)*0.1 - (I34+J34)*0.05 + T34*0.4 ,"") | X34: =IFERROR(IF(ABS(F34)<0.01,"ATM/NEAR",""),"")
A35: =CHAIN_RAW!A35 | B35: =CHAIN_RAW!B35 | C35: =CHAIN_RAW!C35 | D35: =CHAIN_RAW!D35 | E35: =CHAIN_RAW!E35 | F35: =IFERROR((E35-D35)/D35,"") | G35: =IFERROR((CHAIN_RAW!K35+CHAIN_RAW!L35)/2,"") | H35: =IFERROR((CHAIN_RAW!R35+CHAIN_RAW!S35)/2,"") | I35: =IFERROR((CHAIN_RAW!L35-CHAIN_RAW!K35)/MAX(1E-9, G35),"") | J35: =IFERROR((CHAIN_RAW!S35-CHAIN_RAW!R35)/MAX(1E-9, H35),"") | K35: =CHAIN_RAW!G35 | L35: =CHAIN_RAW!N35 | M35: =IFERROR(L35-K35,"") | N35: =CHAIN_RAW!H35 | O35: =CHAIN_RAW!O35 | P35: =IFERROR(O35/N35,"") | Q35: =CHAIN_RAW!I35 | R35: =CHAIN_RAW!P35 | S35: =IFERROR(R35/Q35,"") | T35: =IFERROR((ABS(N35-O35)/MAX(1,(N35+O35)))*EXP(-ABS(E35-CONTROL!E5)/MAX(1,CONTROL!B8)),"") | U35: =IFERROR(IF(O35>N35,"SUPPORT (PE OI)","RESIST (CE OI)"),"") | V35: =IFERROR(IF(Q35>0,IF(R35>0,"BOTH_ADD","CE_ADD_PE_REDUCE"),IF(R35>0,"CE_REDUCE_PE_ADD","BOTH_REDUCE")),"") | W35: =IFERROR( (P35-1)*0.5 + (M35)*0.1 - (I35+J35)*0.05 + T35*0.4 ,"") | X35: =IFERROR(IF(ABS(F35)<0.01,"ATM/NEAR",""),"")
A36: =CHAIN_RAW!A36 | B36: =CHAIN_RAW!B36 | C36: =CHAIN_RAW!C36 | D36: =CHAIN_RAW!D36 | E36: =CHAIN_RAW!E36 | F36: =IFERROR((E36-D36)/D36,"") | G36: =IFERROR((CHAIN_RAW!K36+CHAIN_RAW!L36)/2,"") | H36: =IFERROR((CHAIN_RAW!R36+CHAIN_RAW!S36)/2,"") | I36: =IFERROR((CHAIN_RAW!L36-CHAIN_RAW!K36)/MAX(1E-9, G36),"") | J36: =IFERROR((CHAIN_RAW!S36-CHAIN_RAW!R36)/MAX(1E-9, H36),"") | K36: =CHAIN_RAW!G36 | L36: =CHAIN_RAW!N36 | M36: =IFERROR(L36-K36,"") | N36: =CHAIN_RAW!H36 | O36: =CHAIN_RAW!O36 | P36: =IFERROR(O36/N36,"") | Q36: =CHAIN_RAW!I36 | R36: =CHAIN_RAW!P36 | S36: =IFERROR(R36/Q36,"") | T36: =IFERROR((ABS(N36-O36)/MAX(1,(N36+O36)))*EXP(-ABS(E36-CONTROL!E5)/MAX(1,CONTROL!B8)),"") | U36: =IFERROR(IF(O36>N36,"SUPPORT (PE OI)","RESIST (CE OI)"),"") | V36: =IFERROR(IF(Q36>0,IF(R36>0,"BOTH_ADD","CE_ADD_PE_REDUCE"),IF(R36>0,"CE_REDUCE_PE_ADD","BOTH_REDUCE")),"") | W36: =IFERROR( (P36-1)*0.5 + (M36)*0.1 - (I36+J36)*0.05 + T36*0.4 ,"") | X36: =IFERROR(IF(ABS(F36)<0.01,"ATM/NEAR",""),"")
A37: =CHAIN_RAW!A37 | B37: =CHAIN_RAW!B37 | C37: =CHAIN_RAW!C37 | D37: =CHAIN_RAW!D37 | E37: =CHAIN_RAW!E37 | F37: =IFERROR((E37-D37)/D37,"") | G37: =IFERROR((CHAIN_RAW!K37+CHAIN_RAW!L37)/2,"") | H37: =IFERROR((CHAIN_RAW!R37+CHAIN_RAW!S37)/2,"") | I37: =IFERROR((CHAIN_RAW!L37-CHAIN_RAW!K37)/MAX(1E-9, G37),"") | J37: =IFERROR((CHAIN_RAW!S37-CHAIN_RAW!R37)/MAX(1E-9, H37),"") | K37: =CHAIN_RAW!G37 | L37: =CHAIN_RAW!N37 | M37: =IFERROR(L37-K37,"") | N37: =CHAIN_RAW!H37 | O37: =CHAIN_RAW!O37 | P37: =IFERROR(O37/N37,"") | Q37: =CHAIN_RAW!I37 | R37: =CHAIN_RAW!P37 | S37: =IFERROR(R37/Q37,"") | T37: =IFERROR((ABS(N37-O37)/MAX(1,(N37+O37)))*EXP(-ABS(E37-CONTROL!E5)/MAX(1,CONTROL!B8)),"") | U37: =IFERROR(IF(O37>N37,"SUPPORT (PE OI)","RESIST (CE OI)"),"") | V37: =IFERROR(IF(Q37>0,IF(R37>0,"BOTH_ADD","CE_ADD_PE_REDUCE"),IF(R37>0,"CE_REDUCE_PE_ADD","BOTH_REDUCE")),"") | W37: =IFERROR( (P37-1)*0.5 + (M37)*0.1 - (I37+J37)*0.05 + T37*0.4 ,"") | X37: =IFERROR(IF(ABS(F37)<0.01,"ATM/NEAR",""),"")
A38: =CHAIN_RAW!A38 | B38: =CHAIN_RAW!B38 | C38: =CHAIN_RAW!C38 | D38: =CHAIN_RAW!D38 | E38: =CHAIN_RAW!E38 | F38: =IFERROR((E38-D38)/D38,"") | G38: =IFERROR((CHAIN_RAW!K38+CHAIN_RAW!L38)/2,"") | H38: =IFERROR((CHAIN_RAW!R38+CHAIN_RAW!S38)/2,"") | I38: =IFERROR((CHAIN_RAW!L38-CHAIN_RAW!K38)/MAX(1E-9, G38),"") | J38: =IFERROR((CHAIN_RAW!S38-CHAIN_RAW!R38)/MAX(1E-9, H38),"") | K38: =CHAIN_RAW!G38 | L38: =CHAIN_RAW!N38 | M38: =IFERROR(L38-K38,"") | N38: =CHAIN_RAW!H38 | O38: =CHAIN_RAW!O38 | P38: =IFERROR(O38/N38,"") | Q38: =CHAIN_RAW!I38 | R38: =CHAIN_RAW!P38 | S38: =IFERROR(R38/Q38,"") | T38: =IFERROR((ABS(N38-O38)/MAX(1,(N38+O38)))*EXP(-ABS(E38-CONTROL!E5)/MAX(1,CONTROL!B8)),"") | U38: =IFERROR(IF(O38>N38,"SUPPORT (PE OI)","RESIST (CE OI)"),"") | V38: =IFERROR(IF(Q38>0,IF(R38>0,"BOTH_ADD","CE_ADD_PE_REDUCE"),IF(R38>0,"CE_REDUCE_PE_ADD","BOTH_REDUCE")),"") | W38: =IFERROR( (P38-1)*0.5 + (M38)*0.1 - (I38+J38)*0.05 + T38*0.4 ,"") | X38: =IFERROR(IF(ABS(F38)<0.01,"ATM/NEAR",""),"")
A39: =CHAIN_RAW!A39 | B39: =CHAIN_RAW!B39 | C39: =CHAIN_RAW!C39 | D39: =CHAIN_RAW!D39 | E39: =CHAIN_RAW!E39 | F39: =IFERROR((E39-D39)/D39,"") | G39: =IFERROR((CHAIN_RAW!K39+CHAIN_RAW!L39)/2,"") | H39: =IFERROR((CHAIN_RAW!R39+CHAIN_RAW!S39)/2,"") | I39: =IFERROR((CHAIN_RAW!L39-CHAIN_RAW!K39)/MAX(1E-9, G39),"") | J39: =IFERROR((CHAIN_RAW!S39-CHAIN_RAW!R39)/MAX(1E-9, H39),"") | K39: =CHAIN_RAW!G39 | L39: =CHAIN_RAW!N39 | M39: =IFERROR(L39-K39,"") | N39: =CHAIN_RAW!H39 | O39: =CHAIN_RAW!O39 | P39: =IFERROR(O39/N39,"") | Q39: =CHAIN_RAW!I39 | R39: =CHAIN_RAW!P39 | S39: =IFERROR(R39/Q39,"") | T39: =IFERROR((ABS(N39-O39)/MAX(1,(N39+O39)))*EXP(-ABS(E39-CONTROL!E5)/MAX(1,CONTROL!B8)),"") | U39: =IFERROR(IF(O39>N39,"SUPPORT (PE OI)","RESIST (CE OI)"),"") | V39: =IFERROR(IF(Q39>0,IF(R39>0,"BOTH_ADD","CE_ADD_PE_REDUCE"),IF(R39>0,"CE_REDUCE_PE_ADD","BOTH_REDUCE")),"") | W39: =IFERROR( (P39-1)*0.5 + (M39)*0.1 - (I39+J39)*0.05 + T39*0.4 ,"") | X39: =IFERROR(IF(ABS(F39)<0.01,"ATM/NEAR",""),"")
A40: =CHAIN_RAW!A40 | B40: =CHAIN_RAW!B40 | C40: =CHAIN_RAW!C40 | D40: =CHAIN_RAW!D40 | E40: =CHAIN_RAW!E40 | F40: =IFERROR((E40-D40)/D40,"") | G40: =IFERROR((CHAIN_RAW!K40+CHAIN_RAW!L40)/2,"") | H40: =IFERROR((CHAIN_RAW!R40+CHAIN_RAW!S40)/2,"") | I40: =IFERROR((CHAIN_RAW!L40-CHAIN_RAW!K40)/MAX(1E-9, G40),"") | J40: =IFERROR((CHAIN_RAW!S40-CHAIN_RAW!R40)/MAX(1E-9, H40),"") | K40: =CHAIN_RAW!G40 | L40: =CHAIN_RAW!N40 | M40: =IFERROR(L40-K40,"") | N40: =CHAIN_RAW!H40 | O40: =CHAIN_RAW!O40 | P40: =IFERROR(O40/N40,"") | Q40: =CHAIN_RAW!I40 | R40: =CHAIN_RAW!P40 | S40: =IFERROR(R40/Q40,"") | T40: =IFERROR((ABS(N40-O40)/MAX(1,(N40+O40)))*EXP(-ABS(E40-CONTROL!E5)/MAX(1,CONTROL!B8)),"") | U40: =IFERROR(IF(O40>N40,"SUPPORT (PE OI)","RESIST (CE OI)"),"") | V40: =IFERROR(IF(Q40>0,IF(R40>0,"BOTH_ADD","CE_ADD_PE_REDUCE"),IF(R40>0,"CE_REDUCE_PE_ADD","BOTH_REDUCE")),"") | W40: =IFERROR( (P40-1)*0.5 + (M40)*0.1 - (I40+J40)*0.05 + T40*0.4 ,"") | X40: =IFERROR(IF(ABS(F40)<0.01,"ATM/NEAR",""),"")
...

Sheet SUMMARY
A1: SUMMARY / SIGNALS (blocked if QC_FAIL)
A3: KPI | B3: Value
A4: QC Status | B4: =QC_CHECK!B14
A5: Symbol | B5: =CONTROL!B5
A6: Expiry | B6: =CONTROL!E7
A7: Spot | B7: =CONTROL!E6
A8: ATM Strike | B8: =CONTROL!E5
A9: PCR (Total OI) | B9: =IFERROR(SUM(CHAIN_RAW!O3:O2001)/SUM(CHAIN_RAW!H3:H2001),"")
A10: PCR (Total Volume) | B10: =IFERROR(SUM(CHAIN_RAW!Q3:Q2001)/SUM(CHAIN_RAW!J3:J2001),"")
A11: Max CE OI Strike | B11: =IFERROR(INDEX(CHAIN_RAW!E3:E2001, MATCH(MAX(CHAIN_RAW!H3:H2001), CHAIN_RAW!H3:H2001,0)),"")
A12: Max PE OI Strike | B12: =IFERROR(INDEX(CHAIN_RAW!E3:E2001, MATCH(MAX(CHAIN_RAW!O3:O2001), CHAIN_RAW!O3:O2001,0)),"") | D12: Trade Gate | E12: =IF(OR(QC_CHECK!D21<>"PASS",PROBABILITY_ENGINE!B12<>"PASS"),"NO TRADE ZONE","TRADE OK")
A13: Directional Bias (rule) | B13: =IF(QC_CHECK!B14="FAIL","NO_SIGNAL",IF(AND(F6<>"",F6>1.05),"BULLISH (PCR high)",IF(AND(F6<>"",F6<0.95),"BEARISH (PCR low)","NEUTRAL")))
A14: Confidence (0-100) | B14: =IF(QC_CHECK!B14="FAIL","",IFERROR(MIN(100,MAX(0, (ABS(F6-1)*120) + (1-ABS(F7-1))*10 )),""))
A15: Trade Idea (rule) | B15: =IF(QC_CHECK!B14="FAIL","BLOCKED — FIX QC","If bullish: consider CALL spread near ATM; If bearish: consider PUT spread near ATM; If neutral: wait / iron fly (only if IV high)")
B21: =LEG_SELECTOR!B14 | C21: =LEG_SELECTOR!C14 | D21: =LEG_SELECTOR!D14 | E21: =LEG_SELECTOR!E14 | F21: =IF(E21="","",E21*0.5) | G21: =IF(E21="","",E21*1.0)
B22: =LEG_SELECTOR!B15 | C22: =LEG_SELECTOR!C15 | D22: =LEG_SELECTOR!D15 | E22: =LEG_SELECTOR!E15 | F22: =IF(E22="","",E22*0.5) | G22: =IF(E22="","",E22*1.0)
B23: =LEG_SELECTOR!B16 | C23: =LEG_SELECTOR!C16 | D23: =LEG_SELECTOR!D16 | E23: =LEG_SELECTOR!E16 | F23: =IF(E23="","",E23*0.5) | G23: =IF(E23="","",E23*1.0)
B24: =LEG_SELECTOR!B17 | C24: =LEG_SELECTOR!C17 | D24: =LEG_SELECTOR!D17 | E24: =LEG_SELECTOR!E17 | F24: =IF(E24="","",E24*0.5) | G24: =IF(E24="","",E24*1.0)

Sheet OI_BUILDUP
A1: OI_BUILDUP — Long/Short/Unwind classification (v3)
A3: Row# | B3: Identifier | C3: Strike | D3: Type | E3: LTP | F3: Price Change | G3: OI | H3: OI Change | I3: Buildup Type | J3: Strength (1-5)
A4: 2 | B4: =CHAIN_RAW!D2 | C4: =CHAIN_RAW!A2 | D4: =CHAIN_RAW!C2 | E4: =CHAIN_RAW!E2 | F4: =CHAIN_RAW!F2 | G4: =CHAIN_RAW!I2 | H4: =CHAIN_RAW!Q2 | I4: =LET(pc,F4,oc,H4,IF(OR(pc="",oc=""),"",IF(AND(pc>0,oc>0),"Long Buildup",IF(AND(pc<0,oc>0),"Short Buildup",IF(AND(pc>0,oc<0),"Short Covering",IF(AND(pc<0,oc<0),"Long Unwinding","Flat")))))) | J4: =LET(pc,ABS(F4),oc,ABS(H4),IF(OR(pc="",oc=""),"",MAX(1,MIN(5,ROUND((pc*0.5+oc*0.00001)*5,0))))))
A5: 3 | B5: =CHAIN_RAW!D3 | C5: =CHAIN_RAW!A3 | D5: =CHAIN_RAW!C3 | E5: =CHAIN_RAW!E3 | F5: =CHAIN_RAW!F3 | G5: =CHAIN_RAW!I3 | H5: =CHAIN_RAW!Q3 | I5: =LET(pc,F5,oc,H5,IF(OR(pc="",oc=""),"",IF(AND(pc>0,oc>0),"Long Buildup",IF(AND(pc<0,oc>0),"Short Buildup",IF(AND(pc>0,oc<0),"Short Covering",IF(AND(pc<0,oc<0),"Long Unwinding","Flat")))))) | J5: =LET(pc,ABS(F5),oc,ABS(H5),IF(OR(pc="",oc=""),"",MAX(1,MIN(5,ROUND((pc*0.5+oc*0.00001)*5,0))))))
A6: 4 | B6: =CHAIN_RAW!D4 | C6: =CHAIN_RAW!A4 | D6: =CHAIN_RAW!C4 | E6: =CHAIN_RAW!E4 | F6: =CHAIN_RAW!F4 | G6: =CHAIN_RAW!I4 | H6: =CHAIN_RAW!Q4 | I6: =LET(pc,F6,oc,H6,IF(OR(pc="",oc=""),"",IF(AND(pc>0,oc>0),"Long Buildup",IF(AND(pc<0,oc>0),"Short Buildup",IF(AND(pc>0,oc<0),"Short Covering",IF(AND(pc<0,oc<0),"Long Unwinding","Flat")))))) | J6: =LET(pc,ABS(F6),oc,ABS(H6),IF(OR(pc="",oc=""),"",MAX(1,MIN(5,ROUND((pc*0.5+oc*0.00001)*5,0))))))
A7: 5 | B7: =CHAIN_RAW!D5 | C7: =CHAIN_RAW!A5 | D7: =CHAIN_RAW!C5 | E7: =CHAIN_RAW!E5 | F7: =CHAIN_RAW!F5 | G7: =CHAIN_RAW!I5 | H7: =CHAIN_RAW!Q5 | I7: =LET(pc,F7,oc,H7,IF(OR(pc="",oc=""),"",IF(AND(pc>0,oc>0),"Long Buildup",IF(AND(pc<0,oc>0),"Short Buildup",IF(AND(pc>0,oc<0),"Short Covering",IF(AND(pc<0,oc<0),"Long Unwinding","Flat")))))) | J7: =LET(pc,ABS(F7),oc,ABS(H7),IF(OR(pc="",oc=""),"",MAX(1,MIN(5,ROUND((pc*0.5+oc*0.00001)*5,0))))))
A8: 6 | B8: =CHAIN_RAW!D6 | C8: =CHAIN_RAW!A6 | D8: =CHAIN_RAW!C6 | E8: =CHAIN_RAW!E6 | F8: =CHAIN_RAW!F6 | G8: =CHAIN_RAW!I6 | H8: =CHAIN_RAW!Q6 | I8: =LET(pc,F8,oc,H8,IF(OR(pc="",oc=""),"",IF(AND(pc>0,oc>0),"Long Buildup",IF(AND(pc<0,oc>0),"Short Buildup",IF(AND(pc>0,oc<0),"Short Covering",IF(AND(pc<0,oc<0),"Long Unwinding","Flat")))))) | J8: =LET(pc,ABS(F8),oc,ABS(H8),IF(OR(pc="",oc=""),"",MAX(1,MIN(5,ROUND((pc*0.5+oc*0.00001)*5,0))))))
A9: 7 | B9: =CHAIN_RAW!D7 | C9: =CHAIN_RAW!A7 | D9: =CHAIN_RAW!C7 | E9: =CHAIN_RAW!E7 | F9: =CHAIN_RAW!F7 | G9: =CHAIN_RAW!I7 | H9: =CHAIN_RAW!Q7 | I9: =LET(pc,F9,oc,H9,IF(OR(pc="",oc=""),"",IF(AND(pc>0,oc>0),"Long Buildup",IF(AND(pc<0,oc>0),"Short Buildup",IF(AND(pc>0,oc<0),"Short Covering",IF(AND(pc<0,oc<0),"Long Unwinding","Flat")))))) | J9: =LET(pc,ABS(F9),oc,ABS(H9),IF(OR(pc="",oc=""),"",MAX(1,MIN(5,ROUND((pc*0.5+oc*0.00001)*5,0))))))
A10: 8 | B10: =CHAIN_RAW!D8 | C10: =CHAIN_RAW!A8 | D10: =CHAIN_RAW!C8 | E10: =CHAIN_RAW!E8 | F10: =CHAIN_RAW!F8 | G10: =CHAIN_RAW!I8 | H10: =CHAIN_RAW!Q8 | I10: =LET(pc,F10,oc,H10,IF(OR(pc="",oc=""),"",IF(AND(pc>0,oc>0),"Long Buildup",IF(AND(pc<0,oc>0),"Short Buildup",IF(AND(pc>0,oc<0),"Short Covering",IF(AND(pc<0,oc<0),"Long Unwinding","Flat")))))) | J10: =LET(pc,ABS(F10),oc,ABS(H10),IF(OR(pc="",oc=""),"",MAX(1,MIN(5,ROUND((pc*0.5+oc*0.00001)*5,0))))))
A11: 9 | B11: =CHAIN_RAW!D9 | C11: =CHAIN_RAW!A9 | D11: =CHAIN_RAW!C9 | E11: =CHAIN_RAW!E9 | F11: =CHAIN_RAW!F9 | G11: =CHAIN_RAW!I9 | H11: =CHAIN_RAW!Q9 | I11: =LET(pc,F11,oc,H11,IF(OR(pc="",oc=""),"",IF(AND(pc>0,oc>0),"Long Buildup",IF(AND(pc<0,oc>0),"Short Buildup",IF(AND(pc>0,oc<0),"Short Covering",IF(AND(pc<0,oc<0),"Long Unwinding","Flat")))))) | J11: =LET(pc,ABS(F11),oc,ABS(H11),IF(OR(pc="",oc=""),"",MAX(1,MIN(5,ROUND((pc*0.5+oc*0.00001)*5,0))))))
A12: 10 | B12: =CHAIN_RAW!D10 | C12: =CHAIN_RAW!A10 | D12: =CHAIN_RAW!C10 | E12: =CHAIN_RAW!E10 | F12: =CHAIN_RAW!F10 | G12: =CHAIN_RAW!I10 | H12: =CHAIN_RAW!Q10 | I12: =LET(pc,F12,oc,H12,IF(OR(pc="",oc=""),"",IF(AND(pc>0,oc>0),"Long Buildup",IF(AND(pc<0,oc>0),"Short Buildup",IF(AND(pc>0,oc<0),"Short Covering",IF(AND(pc<0,oc<0),"Long Unwinding","Flat")))))) | J12: =LET(pc,ABS(F12),oc,ABS(H12),IF(OR(pc="",oc=""),"",MAX(1,MIN(5,ROUND((pc*0.5+oc*0.00001)*5,0))))))
A13: 11 | B13: =CHAIN_RAW!D11 | C13: =CHAIN_RAW!A11 | D13: =CHAIN_RAW!C11 | E13: =CHAIN_RAW!E11 | F13: =CHAIN_RAW!F11 | G13: =CHAIN_RAW!I11 | H13: =CHAIN_RAW!Q11 | I13: =LET(pc,F13,oc,H13,IF(OR(pc="",oc=""),"",IF(AND(pc>0,oc>0),"Long Buildup",IF(AND(pc<0,oc>0),"Short Buildup",IF(AND(pc>0,oc<0),"Short Covering",IF(AND(pc<0,oc<0),"Long Unwinding","Flat")))))) | J13: =LET(pc,ABS(F13),oc,ABS(H13),IF(OR(pc="",oc=""),"",MAX(1,MIN(5,ROUND((pc*0.5+oc*0.00001)*5,0))))))
A14: 12 | B14: =CHAIN_RAW!D12 | C14: =CHAIN_RAW!A12 | D14: =CHAIN_RAW!C12 | E14: =CHAIN_RAW!E12 | F14: =CHAIN_RAW!F12 | G14: =CHAIN_RAW!I12 | H14: =CHAIN_RAW!Q12 | I14: =LET(pc,F14,oc,H14,IF(OR(pc="",oc=""),"",IF(AND(pc>0,oc>0),"Long Buildup",IF(AND(pc<0,oc>0),"Short Buildup",IF(AND(pc>0,oc<0),"Short Covering",IF(AND(pc<0,oc<0),"Long Unwinding","Flat")))))) | J14: =LET(pc,ABS(F14),oc,ABS(H14),IF(OR(pc="",oc=""),"",MAX(1,MIN(5,ROUND((pc*0.5+oc*0.00001)*5,0))))))
A15: 13 | B15: =CHAIN_RAW!D13 | C15: =CHAIN_RAW!A13 | D15: =CHAIN_RAW!C13 | E15: =CHAIN_RAW!E13 | F15: =CHAIN_RAW!F13 | G15: =CHAIN_RAW!I13 | H15: =CHAIN_RAW!Q13 | I15: =LET(pc,F15,oc,H15,IF(OR(pc="",oc=""),"",IF(AND(pc>0,oc>0),"Long Buildup",IF(AND(pc<0,oc>0),"Short Buildup",IF(AND(pc>0,oc<0),"Short Covering",IF(AND(pc<0,oc<0),"Long Unwinding","Flat")))))) | J15: =LET(pc,ABS(F15),oc,ABS(H15),IF(OR(pc="",oc=""),"",MAX(1,MIN(5,ROUND((pc*0.5+oc*0.00001)*5,0))))))
... A2003: 2001 | B2003: =CHAIN_RAW!D2001 | C2003: =CHAIN_RAW!A2001 | D2003: =CHAIN_RAW!C2001 | E2003: =CHAIN_RAW!E2001 | F2003: =CHAIN_RAW!F2001 | G2003: =CHAIN_RAW!I2001 | H2003: =CHAIN_RAW!Q2001 | I2003: =LET(pc,F2003,oc,H2003,IF(OR(pc="",oc=""),"",IF(AND(pc>0,oc>0),"Long Buildup",IF(AND(pc<0,oc>0),"Short Buildup",IF(AND(pc>0,oc<0),"Short Covering",IF(AND(pc<0,oc<0),"Long Unwinding","Flat")))))) | J2003: =LET(pc,ABS(F2003),oc,ABS(H2003),IF(OR(pc="",oc=""),"",MAX(1,MIN(5,ROUND((pc*0.5+oc*0.00001)*5,0))))))

Sheet DELTA_PCR
A1: DELTA_PCR — Delta-weighted positioning (v3)
A3: Spot | B3: =CONTROL!B4
A4: ATM | B4: =CHAIN_CALC!B5
A5: Regime | B5: =CHAIN_CALC!B33
A6: Direction | B6: =CHAIN_CALC!B36
A8: Weighted CE OI (Σ OI*|Δ|) | B8: =SUMPRODUCT(--(tblChainRaw[Option Type]="CE"),tblChainRaw[Open Interest],ABS(GREEKS!K4:K2003))
A9: Weighted PE OI (Σ OI*|Δ|) | B9: =SUMPRODUCT(--(tblChainRaw[Option Type]="PE"),tblChainRaw[Open Interest],ABS(GREEKS!K4:K2003))
A10: Delta PCR | B10: =IF(B8=0,"",B9/B8)
A11: Delta Bias | B11: =IF(B10="","",IF(B10>1.05,"Bearish",IF(B10<0.95,"Bullish","Neutral")))

Sheet GAMMA_THETA_MAP
A1: GAMMA_THETA_MAP — Exposure by Strike (v3)
A3: Strike | B3: CE OI | C3: PE OI | D3: CE GammaExp | E3: PE GammaExp | F3: Net GammaExp | G3: CE ThetaExp/day | H3: PE ThetaExp/day | I3: Net ThetaExp/day
A4: =IF(CHAIN_CALC!B5="","",CHAIN_CALC!B5+(-100)*CONTROL!B6) | B4: =SUMIFS(tblChainRaw[Open Interest],tblChainRaw[Strike Price],A4,tblChainRaw[Option Type],"CE") | C4: =SUMIFS(tblChainRaw[Open Interest],tblChainRaw[Strike Price],A4,tblChainRaw[Option Type],"PE") | D4: =LET(s,CONTROL!B4,ls,CONTROL!B5,SUMPRODUCT(--(tblChainRaw[Strike Price]=A4),--(tblChainRaw[Option Type]="CE"),tblChainRaw[Open Interest],GREEKS!L4:L2003)*s^2*ls) | E4: =LET(s,CONTROL!B4,ls,CONTROL!B5,SUMPRODUCT(--(tblChainRaw[Strike Price]=A4),--(tblChainRaw[Option Type]="PE"),tblChainRaw[Open Interest],GREEKS!L4:L2003)*s^2*ls) | F4: =D4-E4 | G4: =LET(ls,CONTROL!B5,SUMPRODUCT(--(tblChainRaw[Strike Price]=A4),--(tblChainRaw[Option Type]="CE"),tblChainRaw[Open Interest],GREEKS!M4:M2003)*ls) | H4: =LET(ls,CONTROL!B5,SUMPRODUCT(--(tblChainRaw[Strike Price]=A4),--(tblChainRaw[Option Type]="PE"),tblChainRaw[Open Interest],GREEKS!M4:M2003)*ls) | I4: =G4+H4
A5: =IF(CHAIN_CALC!B5="","",CHAIN_CALC!B5+(-99)*CONTROL!B6) | B5: =SUMIFS(tblChainRaw[Open Interest],tblChainRaw[Strike Price],A5,tblChainRaw[Option Type],"CE") | C5: =SUMIFS(tblChainRaw[Open Interest],tblChainRaw[Strike Price],A5,tblChainRaw[Option Type],"PE") | D5: =LET(s,CONTROL!B4,ls,CONTROL!B5,SUMPRODUCT(--(tblChainRaw[Strike Price]=A5),--(tblChainRaw[Option Type]="CE"),tblChainRaw[Open Interest],GREEKS!L4:L2003)*s^2*ls) | E5: =LET(s,CONTROL!B4,ls,CONTROL!B5,SUMPRODUCT(--(tblChainRaw[Strike Price]=A5),--(tblChainRaw[Option Type]="PE"),tblChainRaw[Open Interest],GREEKS!L4:L2003)*s^2*ls) | F5: =D5-E5 | G5: =LET(ls,CONTROL!B5,SUMPRODUCT(--(tblChainRaw[Strike Price]=A5),--(tblChainRaw[Option Type]="CE"),tblChainRaw[Open Interest],GREEKS!M4:M2003)*ls) | H5: =LET(ls,CONTROL!B5,SUMPRODUCT(--(tblChainRaw[Strike Price]=A5),--(tblChainRaw[Option Type]="PE"),tblChainRaw[Open Interest],GREEKS!M4:M2003)*ls) | I5: =G5+H5
A6: =IF(CHAIN_CALC!B5="","",CHAIN_CALC!B5+(-98)*CONTROL!B6) | B6: =SUMIFS(tblChainRaw[Open Interest],tblChainRaw[Strike Price],A6,tblChainRaw[Option Type],"CE") | C6: =SUMIFS(tblChainRaw[Open Interest],tblChainRaw[Strike Price],A6,tblChainRaw[Option Type],"PE") | D6: =LET(s,CONTROL!B4,ls,CONTROL!B5,SUMPRODUCT(--(tblChainRaw[Strike Price]=A6),--(tblChainRaw[Option Type]="CE"),tblChainRaw[Open Interest],GREEKS!L4:L2003)*s^2*ls) | E6: =LET(s,CONTROL!B4,ls,CONTROL!B5,SUMPRODUCT(--(tblChainRaw[Strike Price]=A6),--(tblChainRaw[Option Type]="PE"),tblChainRaw[Open Interest],GREEKS!L4:L2003)*s^2*ls) | F6: =D6-E6 | G6: =LET(ls,CONTROL!B5,SUMPRODUCT(--(tblChainRaw[Strike Price]=A6),--(tblChainRaw[Option Type]="CE"),tblChainRaw[Open Interest],GREEKS!M4:M2003)*ls) | H6: =LET(ls,CONTROL!B5,SUMPRODUCT(--(tblChainRaw[Strike Price]=A6),--(tblChainRaw[Option Type]="PE"),tblChainRaw[Open Interest],GREEKS!M4:M2003)*ls) | I6: =G6+H6
A7: =IF(CHAIN_CALC!B5="","",CHAIN_CALC!B5+(-97)*CONTROL!B6) | B7: =SUMIFS(tblChainRaw[Open Interest],tblChainRaw[Strike Price],A7,tblChainRaw[Option Type],"CE") | C7: =SUMIFS(tblChainRaw[Open Interest],tblChainRaw[Strike Price],A7,tblChainRaw[Option Type],"PE") | D7: =LET(s,CONTROL!B4,ls,CONTROL!B5,SUMPRODUCT(--(tblChainRaw[Strike Price]=A7),--(tblChainRaw[Option Type]="CE"),tblChainRaw[Open Interest],GREEKS!L4:L2003)*s^2*ls) | E7: =LET(s,CONTROL!B4,ls,CONTROL!B5,SUMPRODUCT(--(tblChainRaw[Strike Price]=A7),--(tblChainRaw[Option Type]="PE"),tblChainRaw[Open Interest],GREEKS!L4:L2003)*s^2*ls) | F7: =D7-E7 | G7: =LET(ls,CONTROL!B5,SUMPRODUCT(--(tblChainRaw[Strike Price]=A7),--(tblChainRaw[Option Type]="CE"),tblChainRaw[Open Interest],GREEKS!M4:M2003)*ls) | H7: =LET(ls,CONTROL!B5,SUMPRODUCT(--(tblChainRaw[Strike Price]=A7),--(tblChainRaw[Option Type]="PE"),tblChainRaw[Open Interest],GREEKS!M4:M2003)*ls) | I7: =G7+H7
A8: =IF(CHAIN_CALC!B5="","",CHAIN_CALC!B5+(-96)*CONTROL!B6) | B8: =SUMIFS(tblChainRaw[Open Interest],tblChainRaw[Strike Price],A8,tblChainRaw[Option Type],"CE") | C8: =SUMIFS(tblChainRaw[Open Interest],tblChainRaw[Strike Price],A8,tblChainRaw[Option Type],"PE") | D8: =LET(s,CONTROL!B4,ls,CONTROL!B5,SUMPRODUCT(--(tblChainRaw[Strike Price]=A8),--(tblChainRaw[Option Type]="CE"),tblChainRaw[Open Interest],GREEKS!L4:L2003)*s^2*ls) | E8: =LET(s,CONTROL!B4,ls,CONTROL!B5,SUMPRODUCT(--(tblChainRaw[Strike Price]=A8),--(tblChainRaw[Option Type]="PE"),tblChainRaw[Open Interest],GREEKS!L4:L2003)*s^2*ls) | F8: =D8-E8 | G8: =LET(ls,CONTROL!B5,SUMPRODUCT(--(tblChainRaw[Strike Price]=A8),--(tblChainRaw[Option Type]="CE"),tblChainRaw[Open Interest],GREEKS!M4:M2003)*ls) | H8: =LET(ls,CONTROL!B5,SUMPRODUCT(--(tblChainRaw[Strike Price]=A8),--(tblChainRaw[Option Type]="PE"),tblChainRaw[Open Interest],GREEKS!M4:M2003)*ls) | I8: =G8+H8
A9: =IF(CHAIN_CALC!B5="","",CHAIN_CALC!B5+(-95)*CONTROL!B6) | B9: =SUMIFS(tblChainRaw[Open Interest],tblChainRaw[Strike Price],A9,tblChainRaw[Option Type],"CE") | C9: =SUMIFS(tblChainRaw[Open Interest],tblChainRaw[Strike Price],A9,tblChainRaw[Option Type],"PE") | D9: =LET(s,CONTROL!B4,ls,CONTROL!B5,SUMPRODUCT(--(tblChainRaw[Strike Price]=A9),--(tblChainRaw[Option Type]="CE"),tblChainRaw[Open Interest],GREEKS!L4:L2003)*s^2*ls) | E9: =LET(s,CONTROL!B4,ls,CONTROL!B5,SUMPRODUCT(--(tblChainRaw[Strike Price]=A9),--(tblChainRaw[Option Type]="PE"),tblChainRaw[Open Interest],GREEKS!L4:L2003)*s^2*ls) | F9: =D9-E9 | G9: =LET(ls,CONTROL!B5,SUMPRODUCT(--(tblChainRaw[Strike Price]=A9),--(tblChainRaw[Option Type]="CE"),tblChainRaw[Open Interest],GREEKS!M4:M2003)*ls) | H9: =LET(ls,CONTROL!B5,SUMPRODUCT(--(tblChainRaw[Strike Price]=A9),--(tblChainRaw[Option Type]="PE"),tblChainRaw[Open Interest],GREEKS!M4:M2003)*ls) | I9: =G9+H9
A10: =IF(CHAIN_CALC!B5="","",CHAIN_CALC!B5+(-94)*CONTROL!B6) | B10: =SUMIFS(tblChainRaw[Open Interest],tblChainRaw[Strike Price],A10,tblChainRaw[Option Type],"CE") | C10: =SUMIFS(tblChainRaw[Open Interest],tblChainRaw[Strike Price],A10,tblChainRaw[Option Type],"PE") | D10: =LET(s,CONTROL!B4,ls,CONTROL!B5,SUMPRODUCT(--(tblChainRaw[Strike Price]=A10),--(tblChainRaw[Option Type]="CE"),tblChainRaw[Open Interest],GREEKS!L4:L2003)*s^2*ls) | E10: =LET(s,CONTROL!B4,ls,CONTROL!B5,SUMPRODUCT(--(tblChainRaw[Strike Price]=A10),--(tblChainRaw[Option Type]="PE"),tblChainRaw[Open Interest],GREEKS!L4:L2003)*s^2*ls) | F10: =D10-E10 | G10: =LET(ls,CONTROL!B5,SUMPRODUCT(--(tblChainRaw[Strike Price]=A10),--(tblChainRaw[Option Type]="CE"),tblChainRaw[Open Interest],GREEKS!M4:M2003)*ls) | H10: =LET(ls,CONTROL!B5,SUMPRODUCT(--(tblChainRaw[Strike Price]=A10),--(tblChainRaw[Option Type]="PE"),tblChainRaw[Open Interest],GREEKS!M4:M2003)*ls) | I10: =G10+H10
A11: =IF(CHAIN_CALC!B5="","",CHAIN_CALC!B5+(-93)*CONTROL!B6) | B11: =SUMIFS(tblChainRaw[Open Interest],tblChainRaw[Strike Price],A11,tblChainRaw[Option Type],"CE") | C11: =SUMIFS(tblChainRaw[Open Interest],tblChainRaw[Strike Price],A11,tblChainRaw[Option Type],"PE") | D11: =LET(s,CONTROL!B4,ls,CONTROL!B5,SUMPRODUCT(--(tblChainRaw[Strike Price]=A11),--(tblChainRaw[Option Type]="CE"),tblChainRaw[Open Interest],GREEKS!L4:L2003)*s^2*ls) | E11: =LET(s,CONTROL!B4,ls,CONTROL!B5,SUMPRODUCT(--(tblChainRaw[Strike Price]=A11),--(tblChainRaw[Option Type]="PE"),tblChainRaw[Open Interest],GREEKS!L4:L2003)*s^2*ls) | F11: =D11-E11 | G11: =LET(ls,CONTROL!B5,SUMPRODUCT(--(tblChainRaw[Strike Price]=A11),--(tblChainRaw[Option Type]="CE"),tblChainRaw[Open Interest],GREEKS!M4:M2003)*ls) | H11: =LET(ls,CONTROL!B5,SUMPRODUCT(--(tblChainRaw[Strike Price]=A11),--(tblChainRaw[Option Type]="PE"),tblChainRaw[Open Interest],GREEKS!M4:M2003)*ls) | I11: =G11+H11
A12: =IF(CHAIN_CALC!B5="","",CHAIN_CALC!B5+(-92)*CONTROL!B6) | B12: =SUMIFS(tblChainRaw[Open Interest],tblChainRaw[Strike Price],A12,tblChainRaw[Option Type],"CE") | C12: =SUMIFS(tblChainRaw[Open Interest],tblChainRaw[Strike Price],A12,tblChainRaw[Option Type],"PE") | D12: =LET(s,CONTROL!B4,ls,CONTROL!B5,SUMPRODUCT(--(tblChainRaw[Strike Price]=A12),--(tblChainRaw[Option Type]="CE"),tblChainRaw[Open Interest],GREEKS!L4:L2003)*s^2*ls) | E12: =LET(s,CONTROL!B4,ls,CONTROL!B5,SUMPRODUCT(--(tblChainRaw[Strike Price]=A12),--(tblChainRaw[Option Type]="PE"),tblChainRaw[Open Interest],GREEKS!L4:L2003)*s^2*ls) | F12: =D12-E12 | G12: =LET(ls,CONTROL!B5,SUMPRODUCT(--(tblChainRaw[Strike Price]=A12),--(tblChainRaw[Option Type]="CE"),tblChainRaw[Open Interest],GREEKS!M4:M2003)*ls) | H12: =LET(ls,CONTROL!B5,SUMPRODUCT(--(tblChainRaw[Strike Price]=A12),--(tblChainRaw[Option Type]="PE"),tblChainRaw[Open Interest],GREEKS!M4:M2003)*ls) | I12: =G12+H12
